Workbook

Sheet ENTRY SHEET
G1: DAILY REPORT OF APRIL-2026
F2: DATE | G2: .
G3: HOUR METER | J3: KILO METER | M3: MINES TRIPS | R3: REHANDLING C.PLANT | Y3: SIFTING TRIP | AF3: H.S.D REPORT | AN3: REMARKS
F4: VICHELE NO. | G4: OMR | H4: CMR | I4: TOTAL HOURS | J4: OMR | K4: CMR | L4: TOTAL KM | M4: ROM | N4: OB | O4: S.ORE | P4: BD | Q4: TOTAL TRIPS | R4: ROM TRIP | S4: 10\40 TRIP | T4: FINES TRIP | U4: LR TRIP | V4: OB TRIP | W4: REHANDLING TRIP | X4: TOTAL REHANDLING H.R | Y4: 10\40 TRIP | Z4: FINES TRIP | AA4: 10\40 MT | AB4: FINES MT | AC4: SIFTING HOURS | AD4: TOTAL SIFTING TRIP | AE4: TOTAL SIFTING TONES | AF4: OPENING BALANCE | AG4: ISSUE H.S.D | AH4: TOTAL H.S.D | AI4: Diesel Consumption | AJ4: CLOSING BALANCE | AK4: PER HRS CONS. | AL4: Tank capacity | AM4: Tanking Full Required
F5: VOLVO 300-2 | I5: =H5-G5 -> 0 | Q5: =P5+O5+N5+M5 -> 0 | W5: =R5+S5+T5+U5+V5 -> 0 | AD5: =Y5+Z5 -> 0 | AE5: =AA5+AB5 -> 0 | AH5: =AG5+AF5 -> 0 | AI5: =AH5-AJ5 -> 0 | AK5: =AI5/I5 -> #DIV/0! | AL5: 460 | AM5: =AL5-AJ5 -> 460
F6: VOLVO-300-7 | I6: =H6-G6 -> 0 | Q6: =P6+O6+N6+M6 -> 0 | W6: =R6+S6+T6+U6+V6 -> 0 | AD6: =Y6+Z6 -> 0 | AE6: =AA6+AB6 -> 0 | AH6: =AG6+AF6 -> 0 | AI6: =AH6-AJ6 -> 0 | AK6: =AI6/I6 -> #DIV/0! | AL6: 460 | AM6: =AL6-AJ6 -> 460
F7: HITACHI-350 | I7: =H7-G7 -> 0 | Q7: =P7+O7+N7+M7 -> 0 | W7: =R7+S7+T7+U7+V7 -> 0 | AD7: =Y7+Z7 -> 0 | AE7: =AA7+AB7 -> 0 | AH7: =AG7+AF7 -> 0 | AI7: =AH7-AJ7 -> 0 | AK7: =AI7/I7 -> #DIV/0! | AL7: 460 | AM7: =AL7-AJ7 -> 460
F8: VOLVO-480 | I8: =H8-G8 -> 0 | Q8: =P8+O8+N8+M8 -> 0 | W8: =R8+S8+T8+U8+V8 -> 0 | AD8: =Y8+Z8 -> 0 | AE8: =AA8+AB8 -> 0 | AH8: =AG8+AF8 -> 0 | AI8: =AH8-AJ8 -> 0 | AK8: =AI8/I8 -> #DIV/0! | AL8: 600 | AM8: =AL8-AJ8 -> 600
F9: KOMASTU-350 DMC | I9: =H9-G9 -> 0 | W9: =R9+S9+T9+U9+V9 -> 0 | AD9: =Y9+Z9 -> 0 | AE9: =AA9+AB9 -> 0 | AH9: =AG9+AF9 -> 0
F10: VOLVO-300(5)
F11: VOLVO-380
F12: DOZZER D65E
F13: BD 85 DOZER
F14: KOBELCO-380 DMCS
F15: GRADER OD09P-1732
E17: OD09C-1962 | F17: OD09C-1962
E18: OD09C-1964 | F18: OD09C-1964
E19: OD09C1965 | F19: OD09C1965 | I19: =H19-G19 -> 0 | L19: =K19-J19 -> 0 | Q19: =P19+O19+N19+M19 -> 0 | W19: =R19+S19+T19+U19+V19 -> 0 | AD19: =Y19+Z19 -> 0 | AE19: =AA19+AB19 -> 0 | AH19: =AG19+AF19 -> 0 | AI19: =AH19-AJ19 -> 0 | AK19: =AI19/I19 -> #DIV/0! | AL19: 220 | AM19: =AL19-AJ19 -> 220
E20: ODO9C5136 | F20: ODO9C5136 | I20: =H20-G20 -> 0 | L20: =K20-J20 -> 0 | Q20: =P20+O20+N20+M20 -> 0 | W20: =R20+S20+T20+U20+V20 -> 0 | AD20: =Y20+Z20 -> 0 | AE20: =AA20+AB20 -> 0 | AH20: =AG20+AF20 -> 0 | AI20: =AH20-AJ20 -> 0 | AK20: =AI20/I20 -> #DIV/0! | AL20: 220 | AM20: =AL20-AJ20 -> 220
E21: OD09C5137 | F21: OD09C5137 | I21: =H21-G21 -> 0 | L21: =K21-J21 -> 0 | Q21: =P21+O21+N21+M21 -> 0 | W21: =R21+S21+T21+U21+V21 -> 0 | AD21: =Y21+Z21 -> 0 | AE21: =AA21+AB21 -> 0 | AH21: =AG21+AF21 -> 0 | AI21: =AH21-AJ21 -> 0 | AK21: =AI21/I21 -> #DIV/0! | AL21: 220 | AM21: =AL21-AJ21 -> 220
E22: OD09C4623 | F22: OD09C4623 | I22: =H22-G22 -> 0 | L22: =K22-J22 -> 0 | Q22: =P22+O22+N22+M22 -> 0 | W22: =R22+S22+T22+U22+V22 -> 0 | AD22: =Y22+Z22 -> 0 | AE22: =AA22+AB22 -> 0 | AH22: =AG22+AF22 -> 0 | AI22: =AH22-AJ22 -> 0 | AK22: =AI22/I22 -> #DIV/0! | AL22: 220 | AM22: =AL22-AJ22 -> 220
E23: OD09C4624 | F23: OD09C4625 | I23: =H23-G23 -> 0 | L23: =K23-J23 -> 0 | Q23: =P23+O23+N23+M23 -> 0 | W23: =R23+S23+T23+U23+V23 -> 0 | AD23: =Y23+Z23 -> 0 | AE23: =AA23+AB23 -> 0 | AH23: =AG23+AF23 -> 0 | AI23: =AH23-AJ23 -> 0 | AK23: =AI23/I23 -> #DIV/0! | AL23: 220 | AM23: =AL23-AJ23 -> 220
E24: OD09C4625 | F24: OD09C4823 | I24: =H24-G24 -> 0 | L24: =K24-J24 -> 0 | Q24: =P24+O24+N24+M24 -> 0 | W24: =R24+S24+T24+U24+V24 -> 0 | AD24: =Y24+Z24 -> 0 | AE24: =AA24+AB24 -> 0 | AH24: =AG24+AF24 -> 0 | AI24: =AH24-AJ24 -> 0 | AK24: =AI24/I24 -> #DIV/0! | AL24: 220 | AM24: =AL24-AJ24 -> 220
E25: OD09C4823 | F25: OD09C-4824 | I25: =H25-G25 -> 0 | L25: =K25-J25 -> 0 | Q25: =P25+O25+N25+M25 -> 0 | W25: =R25+S25+T25+U25+V25 -> 0 | AD25: =Y25+Z25 -> 0 | AE25: =AA25+AB25 -> 0 | AH25: =AG25+AF25 -> 0 | AI25: =AH25-AJ25 -> 0 | AK25: =AI25/I25 -> #DIV/0! | AL25: 220 | AM25: =AL25-AJ25 -> 220
E26: OD09C-4824 | F26: JH06H-3742 | I26: =H26-G26 -> 0 | L26: =K26-J26 -> 0 | Q26: =P26+O26+N26+M26 -> 0 | W26: =R26+S26+T26+U26+V26 -> 0 | AD26: =Y26+Z26 -> 0 | AE26: =AA26+AB26 -> 0 | AH26: =AG26+AF26 -> 0 | AI26: =AH26-AJ26 -> 0 | AK26: =AI26/I26 -> #DIV/0! | AL26: 220 | AM26: =AL26-AJ26 -> 220
E27: JH06H-3742 | F27: OD09C-4879 | I27: =H27-G27 -> 0 | L27: =K27-J27 -> 0 | Q27: =P27+O27+N27+M27 -> 0 | W27: =R27+S27+T27+U27+V27 -> 0 | AD27: =Y27+Z27 -> 0 | AE27: =AA27+AB27 -> 0 | AH27: =AG27+AF27 -> 0 | AI27: =AH27-AJ27 -> 0 | AK27: =AI27/I27 -> #DIV/0! | AL27: 220 | AM27: =AL27-AJ27 -> 220
E28: OD09C-4879 | F28: OD09C-1371 | I28: =H28-G28 -> 0 | L28: =K28-J28 -> 0 | Q28: =P28+O28+N28+M28 -> 0 | W28: =R28+S28+T28+U28+V28 -> 0 | AD28: =Y28+Z28 -> 0 | AE28: =AA28+AB28 -> 0 | AH28: =AG28+AF28 -> 0 | AI28: =AH28-AJ28 -> 0 | AK28: =AI28/I28 -> #DIV/0! | AL28: 220 | AM28: =AL28-AJ28 -> 220
E29: OD09C-8163 | F29: OD09C-4878 | I29: =H29-G29 -> 0 | L29: =K29-J29 -> 0 | Q29: =P29+O29+N29+M29 -> 0 | W29: =R29+S29+T29+U29+V29 -> 0 | AD29: =Y29+Z29 -> 0 | AE29: =AA29+AB29 -> 0 | AH29: =AG29+AF29 -> 0 | AI29: =AH29-AJ29 -> 0 | AK29: =AI29/I29 -> #DIV/0! | AL29: 240 | AM29: =AL29-AJ29 -> 240
E30: OD09A-5106 | F30: OD09C-8163 | I30: =H30-G30 -> 0 | L30: =K30-J30 -> 0 | Q30: =P30+O30+N30+M30 -> 0 | W30: =R30+S30+T30+U30+V30 -> 0 | AD30: =Y30+Z30 -> 0 | AE30: =AA30+AB30 -> 0 | AH30: =AG30+AF30 -> 0 | AK30: =AI30/I30 -> #DIV/0! | AL30: 240 | AM30: =AL30-AJ30 -> 240
E31: OD09C-8164 | F31: OD09A-5106 | I31: =H31-G31 -> 0 | L31: =K31-J31 -> 0 | Q31: =P31+O31+N31+M31 -> 0 | W31: =R31+S31+T31+U31+V31 -> 0 | AD31: =Y31+Z31 -> 0 | AE31: =AA31+AB31 -> 0 | AH31: =AG31+AF31 -> 0 | AI31: =AH31-AJ31 -> 0 | AK31: =AI31/I31 -> #DIV/0! | AL31: 240 | AM31: =AL31-AJ31 -> 240
E32: OD09C-3710 | F32: OD09C-8164 | I32: =H32-G32 -> 0 | L32: =K32-J32 -> 0 | Q32: =P32+O32+N32+M32 -> 0 | W32: =R32+S32+T32+U32+V32 -> 0 | AD32: =Y32+Z32 -> 0 | AE32: =AA32+AB32 -> 0 | AH32: =AG32+AF32 -> 0 | AI32: =AH32-AJ32 -> 0 | AK32: =AI32/I32 -> #DIV/0! | AL32: 240 | AM32: =AL32-AJ32 -> 240
E33: OD09A-5666 | F33: OD09C-1373 | I33: =H33-G33 -> 0 | L33: =K33-J33 -> 0 | Q33: =P33+O33+N33+M33 -> 0 | W33: =R33+S33+T33+U33+V33 -> 0 | AD33: =Y33+Z33 -> 0 | AE33: =AA33+AB33 -> 0 | AH33: =AG33+AF33 -> 0 | AI33: =AH33-AJ33 -> 0 | AK33: =AI33/I33 -> #DIV/0! | AL33: 240 | AM33: =AL33-AJ33 -> 240
E34: OD09A-6059 | F34: OD09A-5666 | I34: =H34-G34 -> 0 | L34: =K34-J34 -> 0 | Q34: =P34+O34+N34+M34 -> 0 | W34: =R34+S34+T34+U34+V34 -> 0 | AD34: =Y34+Z34 -> 0 | AE34: =AA34+AB34 -> 0 | AH34: =AG34+AF34 -> 0 | AI34: =AH34-AJ34 -> 0 | AK34: =AI34/I34 -> #DIV/0! | AL34: 240 | AM34: =AL34-AJ34 -> 240
E35: JH06H-9654 | F35: OD09A-6059 | I35: =H35-G35 -> 0 | L35: =K35-J35 -> 0 | Q35: =P35+O35+N35+M35 -> 0 | W35: =R35+S35+T35+U35+V35 -> 0 | AD35: =Y35+Z35 -> 0 | AE35: =AA35+AB35 -> 0 | AH35: =AG35+AF35 -> 0 | AI35: =AH35-AJ35 -> 0 | AK35: =AI35/I35 -> #DIV/0! | AL35: 240 | AM35: =AL35-AJ35 -> 240
E36: OD09A-5105 | F36: JH06H-9654 | I36: =H36-G36 -> 0 | L36: =K36-J36 -> 0 | Q36: =P36+O36+N36+M36 -> 0 | W36: =R36+S36+T36+U36+V36 -> 0 | AD36: =Y36+Z36 -> 0 | AE36: =AA36+AB36 -> 0 | AH36: =AG36+AF36 -> 0 | AI36: =AH36-AJ36 -> 0 | AK36: =AI36/I36 -> #DIV/0! | AL36: 240 | AM36: =AL36-AJ36 -> 240
E37: JH06G-4703 | F37: OD09A-5105 | I37: =H37-G37 -> 0 | L37: =K37-J37 -> 0 | Q37: =P37+O37+N37+M37 -> 0 | W37: =R37+S37+T37+U37+V37 -> 0 | AD37: =Y37+Z37 -> 0 | AE37: =AA37+AB37 -> 0 | AH37: =AG37+AF37 -> 0 | AI37: =AH37-AJ37 -> 0 | AK37: =AI37/I37 -> #DIV/0! | AL37: 240 | AM37: =AL37-AJ37 -> 240
E38: JH06H-5348 | F38: JH06G-4703 | I38: =H38-G38 -> 0 | L38: =K38-J38 -> 0 | Q38: =P38+O38+N38+M38 -> 0 | W38: =R38+S38+T38+U38+V38 -> 0 | AD38: =Y38+Z38 -> 0 | AE38: =AA38+AB38 -> 0 | AH38: =AG38+AF38 -> 0 | AI38: =AH38-AJ38 -> 0 | AK38: =AI38/I38 -> #DIV/0! | AL38: 240 | AM38: =AL38-AJ38 -> 240
E39: JH06G-5437 | F39: JH06H-5348 | I39: =H39-G39 -> 0 | L39: =K39-J39 -> 0 | Q39: =P39+O39+N39+M39 -> 0 | W39: =R39+S39+T39+U39+V39 -> 0 | AD39: =Y39+Z39 -> 0 | AE39: =AA39+AB39 -> 0 | AH39: =AG39+AF39 -> 0 | AI39: =AH39-AJ39 -> 0 | AK39: =AI39/I39 -> #DIV/0! | AL39: 260 | AM39: =AL39-AJ39 -> 260
E40: OD09Z-1273 | F40: OD09K-5036 | I40: =H40-G40 -> 0 | L40: =K40-J40 -> 0 | Q40: =P40+O40+N40+M40 -> 0 | W40: =R40+S40+T40+U40+V40 -> 0 | AD40: =Y40+Z40 -> 0 | AE40: =AA40+AB40 -> 0 | AH40: =AG40+AF40 -> 0 | AI40: =AH40-AJ40 -> 0 | AK40: =AI40/I40 -> #DIV/0! | AL40: 260 | AM40: =AL40-AJ40 -> 260
E41: OD09Z-1274 | F41: OD09K-1394 | I41: =H41-G41 -> 0 | L41: =K41-J41 -> 0 | Q41: =P41+O41+N41+M41 -> 0 | W41: =R41+S41+T41+U41+V41 -> 0 | AD41: =Y41+Z41 -> 0 | AE41: =AA41+AB41 -> 0 | AH41: =AG41+AF41 -> 0 | AI41: =AH41-AJ41 -> 0 | AK41: =AI41/I41 -> #DIV/0! | AL41: 240 | AM41: =AL41-AJ41 -> 240
...

Sheet 01
A1: ='ENTRY SHEET'!G1 -> DAILY REPORT OF APRIL-2026
R2: DATE | S2: 46113
B3: HOUR METER | R3: KILO METER | U3: MINES TRIPS | Z3: REHANDLING C.PLANT | AH3: SIFTING TRIP | AN3: H.S.D REPORT | AV3: REMARKS | AW3: HSD Consumption Details
A4: VICHELE NO. | B4: OMR | C4: CMR | D4: TOTAL HOURS | E4: PLAN HRS | F4: Breakfast & Lunch hrs | G4: MINES RHS | H4: REHANDLING HRS | I4: SHIFTING HRS | J4: CRUSHER HRS | K4: SCREEN PLANT | L4: LOKO TRACK | M4: BREAKING HRS | N4: BREAKDOWN HRS | O4: Marching HRS | P4: Mining Development hrs | Q4: TOTAL HRS | R4: OMR | S4: CMR | T4: TOTAL KM | U4: ROM TRIPS | V4: OB TRIPS | W4: S.ORE | X4: BD | Y4: TOTAL TRIPS | Z4: ROM TRIP | AA4: 10\40 TRIP | AB4: FINES TRIP | AC4: LR TRIP | AD4: SUBGRADE TO CRUSHER | AE4: SCREEN TO CRUSHER | AF4: OB TRIPS | AG4: REHANDLING TRIP | AH4: 10\40 TRIP | AI4: FINES TRIP | AJ4: 10\40 MT | AK4: FINES MT | AL4: TOTAL SIFTING TRIP | AM4: TOTAL SIFTING TONES | AN4: OPENING BALANCE | AO4: ISSUE H.S.D | AP4: TOTAL H.S.D | AQ4: Diesel Consumption | AR4: CLOSING BALANCE | AS4: PER HRS CONS. | AT4: Tank capacity | AU4: Tanking Full Required | AW4: SHIFTING | AX4: Rehandling | AY4: NW | AZ4: LOKA | BA4: BHP | BB4: MINES | BC4: POWER
A5: ='ENTRY SHEET'!F5 -> VOLVO 300-2 | B5: =_xlfn.XLOOKUP(A5,'[1]31'!$A:$A,'[1]31'!$C:$C) -> 21964.1 | C5: 21964.1 | D5: =C5-B5 -> 0 | E5: 12 | G5: =D5-H5-I5-J5-K5-L5-M5-N5-O5-P5 -> 0 | Q5: =F5+G5+H5+I5+J5+K5+L5+M5+N5+O5+P5 -> 0 | Y5: =X5+W5+V5+U5 -> 0 | AG5: =Z5+AA5+AB5+AC5+AD5+AE5+AF5 -> 0 | AL5: =AH5+AI5 -> 0 | AM5: =AJ5+AK5 -> 0 | AN5: =_xlfn.XLOOKUP(A5,'[1]31'!$A:$A,'[1]31'!$AR:$AR) -> 350 | AP5: =AO5+AN5 -> 350 | AQ5: =AP5-AR5 -> 0 | AR5: 350 | AS5: =SUM(AQ5/D5,0) -> #DIV/0! | AT5: 470 | AU5: =AT5-AR5 -> 120 | AW5: =ROUNDUP(I5*AS5,0) -> #DIV/0! | AX5: =ROUNDUP(H5*AS5,0) -> #DIV/0! | AY5: =ROUNDUP(J5*AS5,0) -> #DIV/0! | BB5: =AQ5-AW5-AX5-AY5 -> #DIV/0!
A6: ='ENTRY SHEET'!F6 -> VOLVO-300-7 | B6: =_xlfn.XLOOKUP(A6,'[1]31'!$A:$A,'[1]31'!$C:$C) -> 17645.4 | C6: 17654.6 | D6: =C6-B6 -> 9.2 | E6: 12 | G6: =D6-H6-I6-J6-K6-L6-M6-N6-O6-P6 -> 9.2 | Q6: =F6+G6+H6+I6+J6+K6+L6+M6+N6+O6+P6 -> 9.2 | U6: 31 | V6: 88 | Y6: =X6+W6+V6+U6 -> 119 | AG6: =Z6+AA6+AB6+AC6+AD6+AE6+AF6 -> 0 | AL6: =AH6+AI6 -> 0 | AM6: =AJ6+AK6 -> 0 | AN6: =_xlfn.XLOOKUP(A6,'[1]31'!$A:$A,'[1]31'!$AR:$AR) -> 228 | AO6: 387 | AP6: =AO6+AN6 -> 615 | AQ6: =AP6-AR6 -> 480 | AR6: 135 | AS6: =SUM(AQ6/D6,0) -> 52.173913 | AT6: 470 | AU6: =AT6-AR6 -> 335 | AW6: =ROUNDUP(I6*AS6,0) -> 0 | AX6: =ROUNDUP(H6*AS6,0) -> 0 | AY6: =ROUNDUP(J6*AS6,0) -> 0 | BB6: =AQ6-AW6-AX6-AY6 -> 480
A7: ='ENTRY SHEET'!F7 -> HITACHI-350 | B7: =_xlfn.XLOOKUP(A7,'[1]31'!$A:$A,'[1]31'!$C:$C) -> 15783.5 | C7: 15791.9 | D7: =C7-B7 -> 8.4 | E7: 12 | G7: =D7-H7-I7-J7-K7-L7-M7-N7-O7-P7 -> 4 | H7: 4.4 | Q7: =F7+G7+H7+I7+J7+K7+L7+M7+N7+O7+P7 -> 8.4 | V7: 41 | Y7: =X7+W7+V7+U7 -> 41 | AD7: 29 | AG7: =Z7+AA7+AB7+AC7+AD7+AE7+AF7 -> 29 | AL7: =AH7+AI7 -> 0 | AM7: =AJ7+AK7 -> 0 | AN7: =_xlfn.XLOOKUP(A7,'[1]31'!$A:$A,'[1]31'!$AR:$AR) -> 329 | AO7: 295 | AP7: =AO7+AN7 -> 624 | AQ7: =AP7-AR7 -> 252 | AR7: 372 | AS7: =SUM(AQ7/D7,0) -> 30 | AT7: 630 | AU7: =AT7-AR7 -> 258 | AW7: =ROUNDUP(I7*AS7,0) -> 0 | AX7: =ROUNDUP(H7*AS7,0) -> 133 | AY7: =ROUNDUP(J7*AS7,0) -> 0 | BB7: =AQ7-AW7-AX7-AY7 -> 119
A8: ='ENTRY SHEET'!F8 -> VOLVO-480 | B8: =_xlfn.XLOOKUP(A8,'[1]31'!$A:$A,'[1]31'!$C:$C) -> 0 | D8: =C8-B8 -> 0 | E8: 12 | G8: =D8-H8-I8-J8-K8-L8-M8-N8-O8-P8 -> 0 | Q8: =F8+G8+H8+I8+J8+K8+L8+M8+N8+O8+P8 -> 0 | Y8: =X8+W8+V8+U8 -> 0 | AG8: =Z8+AA8+AB8+AC8+AD8+AE8+AF8 -> 0 | AL8: =AH8+AI8 -> 0 | AM8: =AJ8+AK8 -> 0 | AN8: =_xlfn.XLOOKUP(A8,'[1]31'!$A:$A,'[1]31'!$AR:$AR) -> 240 | AP8: =AO8+AN8 -> 240 | AQ8: =AP8-AR8 -> 0 | AR8: 240 | AS8: =SUM(AQ8/D8,0) -> #DIV/0! | AT8: 650 | AU8: =AT8-AR8 -> 410 | AW8: =ROUNDUP(I8*AS8,0) -> #DIV/0! | AX8: =ROUNDUP(H8*AS8,0) -> #DIV/0! | AY8: =ROUNDUP(J8*AS8,0) -> #DIV/0! | BB8: =AQ8-AW8-AX8-AY8 -> #DIV/0!
A9: ='ENTRY SHEET'!F9 -> KOMASTU-350 DMC | B9: =_xlfn.XLOOKUP(A9,'[1]31'!$A:$A,'[1]31'!$C:$C) -> 12573.9 | C9: 12582.8 | D9: =C9-B9 -> 8.9 | E9: 12 | G9: =D9-H9-I9-J9-K9-L9-M9-N9-O9-P9 -> 8.9 | Q9: =F9+G9+H9+I9+J9+K9+L9+M9+N9+O9+P9 -> 8.9 | V9: 65 | Y9: =X9+W9+V9+U9 -> 65 | AG9: =Z9+AA9+AB9+AC9+AD9+AE9+AF9 -> 0 | AL9: =AH9+AI9 -> 0 | AM9: =AJ9+AK9 -> 0 | AN9: =_xlfn.XLOOKUP(A9,'[1]31'!$A:$A,'[1]31'!$AR:$AR) -> 0 | AP9: =AO9+AN9 -> 0 | AQ9: =AP9-AR9 -> 0 | AS9: =SUM(AQ9/D9,0) -> 0 | AT9: 0 | AU9: =AT9-AR9 -> 0 | AW9: =ROUNDUP(I9*AS9,0) -> 0 | AX9: =ROUNDUP(H9*AS9,0) -> 0 | AY9: =ROUNDUP(J9*AS9,0) -> 0 | BB9: =AQ9-AW9-AX9-AY9 -> 0
A10: ='ENTRY SHEET'!F10 -> VOLVO-300(5) | B10: 0 | D10: =C10-B10 -> 0 | E10: 12 | G10: =D10-H10-I10-J10-K10-L10-M10-N10-O10-P10 -> 0 | Q10: =F10+G10+H10+I10+J10+K10+L10+M10+N10+O10+P10 -> 0 | Y10: =X10+W10+V10+U10 -> 0 | AG10: =Z10+AA10+AB10+AC10+AD10+AE10+AF10 -> 0 | AL10: =AH10+AI10 -> 0 | AM10: =AJ10+AK10 -> 0 | AN10: 0 | AP10: =AO10+AN10 -> 0 | AQ10: =AP10-AR10 -> 0 | AT10: 0 | AW10: =ROUNDUP(I10*AS10,0) -> 0 | AX10: =ROUNDUP(H10*AS10,0) -> 0 | AY10: =ROUNDUP(J10*AS10,0) -> 0 | BB10: =AQ10-AW10-AX10-AY10 -> 0
A11: ='ENTRY SHEET'!F11 -> VOLVO-380 | B11: 0 | D11: =C11-B11 -> 0 | E11: 12 | G11: =D11-H11-I11-J11-K11-L11-M11-N11-O11-P11 -> 0 | Q11: =F11+G11+H11+I11+J11+K11+L11+M11+N11+O11+P11 -> 0 | Y11: =X11+W11+V11+U11 -> 0 | AG11: =Z11+AA11+AB11+AC11+AD11+AE11+AF11 -> 0 | AL11: =AH11+AI11 -> 0 | AM11: =AJ11+AK11 -> 0 | AN11: 0 | AP11: =AO11+AN11 -> 0 | AQ11: =AP11-AR11 -> 0 | AT11: 0 | AW11: =ROUNDUP(I11*AS11,0) -> 0 | AX11: =ROUNDUP(H11*AS11,0) -> 0 | AY11: =ROUNDUP(J11*AS11,0) -> 0 | BB11: =AQ11-AW11-AX11-AY11 -> 0
A12: ='ENTRY SHEET'!F12 -> DOZZER D65E | B12: =_xlfn.XLOOKUP(A12,'[1]31'!$A:$A,'[1]31'!$C:$C) -> 2213.8 | C12: 2222.5 | D12: =C12-B12 -> 8.7 | E12: 12 | G12: =D12-H12-I12-J12-K12-L12-M12-N12-O12-P12 -> 8.7 | Q12: =F12+G12+H12+I12+J12+K12+L12+M12+N12+O12+P12 -> 8.7 | Y12: =X12+W12+V12+U12 -> 0 | AG12: =Z12+AA12+AB12+AC12+AD12+AE12+AF12 -> 0 | AL12: =AH12+AI12 -> 0 | AM12: =AJ12+AK12 -> 0 | AN12: =_xlfn.XLOOKUP(A12,'[1]31'!$A:$A,'[1]31'!$AR:$AR) -> 325 | AP12: =AO12+AN12 -> 325 | AQ12: =AP12-AR12 -> 125 | AR12: 200 | AS12: =SUM(AQ12/D12,0) -> 14.367816 | AT12: 350 | AU12: =AT12-AR12 -> 150 | AW12: =ROUNDUP(I12*AS12,0) -> 0 | AX12: =ROUNDUP(H12*AS12,0) -> 0 | AY12: =ROUNDUP(J12*AS12,0) -> 0 | BB12: =AQ12-AW12-AX12-AY12 -> 125
A13: ='ENTRY SHEET'!F13 -> BD 85 DOZER | B13: =_xlfn.XLOOKUP(A13,'[1]31'!$A:$A,'[1]31'!$C:$C) -> 221.7 | C13: 228.3 | D13: =C13-B13 -> 6.6 | E13: 12 | G13: =D13-H13-I13-J13-K13-L13-M13-N13-O13-P13 -> 6.6 | Q13: =F13+G13+H13+I13+J13+K13+L13+M13+N13+O13+P13 -> 6.6 | Y13: =X13+W13+V13+U13 -> 0 | AG13: =Z13+AA13+AB13+AC13+AD13+AE13+AF13 -> 0 | AL13: =AH13+AI13 -> 0 | AM13: =AJ13+AK13 -> 0 | AN13: =_xlfn.XLOOKUP(A13,'[1]31'!$A:$A,'[1]31'!$AR:$AR) -> 85 | AO13: 200 | AP13: =AO13+AN13 -> 285 | AQ13: =AP13-AR13 -> 100 | AR13: 185 | AS13: =SUM(AQ13/D13,0) -> 15.151515 | AT13: 350 | AU13: =AT13-AR13 -> 165 | AW13: =ROUNDUP(I13*AS13,0) -> 0 | AX13: =ROUNDUP(H13*AS13,0) -> 0 | AY13: =ROUNDUP(J13*AS13,0) -> 0 | BB13: =AQ13-AW13-AX13-AY13 -> 100
A14: ='ENTRY SHEET'!F14 -> KOBELCO-380 DMCS | B14: 0 | D14: =C14-B14 -> 0 | E14: 12 | G14: =D14-H14-I14-J14-K14-L14-M14-N14-O14-P14 -> 0 | Q14: =F14+G14+H14+I14+J14+K14+L14+M14+N14+O14+P14 -> 0 | Y14: =X14+W14+V14+U14 -> 0 | AG14: =Z14+AA14+AB14+AC14+AD14+AE14+AF14 -> 0 | AL14: =AH14+AI14 -> 0 | AM14: =AJ14+AK14 -> 0 | AN14: 0 | AP14: =AO14+AN14 -> 0 | AQ14: =AP14-AR14 -> 0 | AS14: =SUM(AQ14/D14,0) -> #DIV/0! | AT14: 350 | AU14: =AT14-AR14 -> 350 | AW14: =ROUNDUP(I14*AS14,0) -> #DIV/0! | AX14: =ROUNDUP(H14*AS14,0) -> #DIV/0! | AY14: =ROUNDUP(J14*AS14,0) -> #DIV/0! | BB14: =AQ14-AW14-AX14-AY14 -> #DIV/0!
A15: ='ENTRY SHEET'!F15 -> GRADER OD09P-1732 | B15: =_xlfn.XLOOKUP(A15,'[1]31'!$A:$A,'[1]31'!$C:$C) -> 4551.5 | C15: 4551.5 | D15: =C15-B15 -> 0 | E15: 12 | G15: =D15-H15-I15-J15-K15-L15-M15-N15-O15-P15 -> 0 | Q15: =F15+G15+H15+I15+J15+K15+L15+M15+N15+O15+P15 -> 0 | Y15: =X15+W15+V15+U15 -> 0 | AG15: =Z15+AA15+AB15+AC15+AD15+AE15+AF15 -> 0 | AL15: =AH15+AI15 -> 0 | AM15: =AJ15+AK15 -> 0 | AN15: =_xlfn.XLOOKUP(A15,'[1]31'!$A:$A,'[1]31'!$AR:$AR) -> 70 | AP15: =AO15+AN15 -> 70 | AQ15: =AP15-AR15 -> 0 | AR15: 70 | AS15: =SUM(AQ15/D15,0) -> #DIV/0! | AT15: 350 | AU15: =AT15-AR15 -> 280 | AW15: =ROUNDUP(I15*AS15,0) -> #DIV/0! | AX15: =ROUNDUP(H15*AS15,0) -> #DIV/0! | AY15: =ROUNDUP(J15*AS15,0) -> #DIV/0! | BB15: =AQ15-AW15-AX15-AY15 -> #DIV/0!
A16: ='ENTRY SHEET'!F16 -> 0 | B16: =_xlfn.XLOOKUP(A16,'[1]31'!$A:$A,'[1]31'!$C:$C) -> 0 | D16: =C16-B16 -> 0 | E16: 12 | Q16: =F16+G16+H16+I16+J16+K16+L16+M16+N16+O16+P16 -> 0 | Y16: =X16+W16+V16+U16 -> 0 | AG16: =Z16+AA16+AB16+AC16+AD16+AE16+AF16 -> 0 | AL16: =AH16+AI16 -> 0 | AM16: =AJ16+AK16 -> 0 | AN16: =_xlfn.XLOOKUP(A16,'[1]31'!$A:$A,'[1]31'!$AR:$AR) -> 0 | AP16: =AO16+AN16 -> 0 | AQ16: =AP16-AR16 -> 0 | AS16: =SUM(AQ16/D16,0) -> #DIV/0! | AT16: 0 | AU16: =AT16-AR16 -> 0 | AW16: =ROUNDUP(I16*AS16,0) -> #DIV/0! | AX16: =ROUNDUP(H16*AS16,0) -> #DIV/0! | AY16: =ROUNDUP(J16*AS16,0) -> #DIV/0! | BB16: =AQ16-AW16-AX16-AY16 -> #DIV/0!
A17: ='ENTRY SHEET'!F17 -> OD09C-1962 | B17: =_xlfn.XLOOKUP(A17,'[1]31'!$A:$A,'[1]31'!$C:$C) -> 20692.6 | C17: 20692.6 | D17: =C17-B17 -> 0 | E17: 12 | G17: =D17-H17-I17 -> 0 | Q17: =F17+G17+H17+I17+J17+K17+L17+M17+N17+O17+P17 -> 0 | R17: =_xlfn.XLOOKUP(A17,'[1]31'!$A:$A,'[1]31'!$S:$S) -> 156139.3 | S17: 156139.3 | T17: =S17-R17 -> 0 | Y17: =X17+W17+V17+U17 -> 0 | AG17: =Z17+AA17+AB17+AC17+AD17+AE17+AF17 -> 0 | AL17: =AH17+AI17 -> 0 | AM17: =AJ17+AK17 -> 0 | AN17: =_xlfn.XLOOKUP(A17,'[1]31'!$A:$A,'[1]31'!$AR:$AR) -> 115 | AP17: =AO17+AN17 -> 115 | AQ17: =AP17-AR17 -> 0 | AR17: 115 | AS17: =SUM(AQ17/D17,0) -> #DIV/0! | AT17: 250 | AU17: =AT17-AR17 -> 135 | AW17: =ROUNDUP(I17*AS17,0) -> #DIV/0! | AX17: =ROUNDUP(H17*AS17,0) -> #DIV/0! | AY17: =ROUNDUP(J17*AS17,0) -> #DIV/0! | BB17: =AQ17-AW17-AX17-AY17 -> #DIV/0!
A18: ='ENTRY SHEET'!F18 -> OD09C-1964 | B18: =_xlfn.XLOOKUP(A18,'[1]31'!$A:$A,'[1]31'!$C:$C) -> 14385.27 | C18: 14393 | D18: =C18-B18 -> 7.73 | E18: 12 | G18: =D18-H18-I18 -> 7.73 | Q18: =F18+G18+H18+I18+J18+K18+L18+M18+N18+O18+P18 -> 7.73 | R18: =_xlfn.XLOOKUP(A18,'[1]31'!$A:$A,'[1]31'!$S:$S) -> 152450.2 | S18: 152484 | T18: =S18-R18 -> 33.8 | U18: 3 | V18: 10 | Y18: =X18+W18+V18+U18 -> 13 | AG18: =Z18+AA18+AB18+AC18+AD18+AE18+AF18 -> 0 | AL18: =AH18+AI18 -> 0 | AM18: =AJ18+AK18 -> 0 | AN18: =_xlfn.XLOOKUP(A18,'[1]31'!$A:$A,'[1]31'!$AR:$AR) -> 90 | AO18: 100 | AP18: =AO18+AN18 -> 190 | AQ18: =AP18-AR18 -> 50 | AR18: 140 | AS18: =SUM(AQ18/D18,0) -> 6.4683053 | AT18: 250 | AU18: =AT18-AR18 -> 110 | AW18: =ROUNDUP(I18*AS18,0) -> 0 | AX18: =ROUNDUP(H18*AS18,0) -> 0 | AY18: =ROUNDUP(J18*AS18,0) -> 0 | BB18: =AQ18-AW18-AX18-AY18 -> 50
A19: ='ENTRY SHEET'!F19 -> OD09C1965 | B19: =_xlfn.XLOOKUP(A19,'[1]31'!$A:$A,'[1]31'!$C:$C) -> 16565.8 | C19: 16565.8 | D19: =C19-B19 -> 0 | E19: 12 | G19: =D19-H19-I19 -> 0 | Q19: =F19+G19+H19+I19+J19+K19+L19+M19+N19+O19+P19 -> 0 | R19: =_xlfn.XLOOKUP(A19,'[1]31'!$A:$A,'[1]31'!$S:$S) -> 166053.3 | S19: 166053.3 | T19: =S19-R19 -> 0 | Y19: =X19+W19+V19+U19 -> 0 | AG19: =Z19+AA19+AB19+AC19+AD19+AE19+AF19 -> 0 | AL19: =AH19+AI19 -> 0 | AM19: =AJ19+AK19 -> 0 | AN19: =_xlfn.XLOOKUP(A19,'[1]31'!$A:$A,'[1]31'!$AR:$AR) -> 0 | AP19: =AO19+AN19 -> 0 | AQ19: =AP19-AR19 -> 0 | AS19: =SUM(AQ19/D19,0) -> #DIV/0! | AT19: 250 | AU19: =AT19-AR19 -> 250 | AW19: =ROUNDUP(I19*AS19,0) -> #DIV/0! | AX19: =ROUNDUP(H19*AS19,0) -> #DIV/0! | AY19: =ROUNDUP(J19*AS19,0) -> #DIV/0! | BB19: =AQ19-AW19-AX19-AY19 -> #DIV/0!
A20: ='ENTRY SHEET'!F20 -> ODO9C5136 | B20: =_xlfn.XLOOKUP(A20,'[1]31'!$A:$A,'[1]31'!$C:$C) -> 17052.5 | C20: 17052.5 | D20: =C20-B20 -> 0 | E20: 12 | G20: =D20-H20-I20 -> 0 | Q20: =F20+G20+H20+I20+J20+K20+L20+M20+N20+O20+P20 -> 0 | R20: =_xlfn.XLOOKUP(A20,'[1]31'!$A:$A,'[1]31'!$S:$S) -> 125216 | S20: 125216 | T20: =S20-R20 -> 0 | Y20: =X20+W20+V20+U20 -> 0 | AG20: =Z20+AA20+AB20+AC20+AD20+AE20+AF20 -> 0 | AL20: =AH20+AI20 -> 0 | AM20: =AJ20+AK20 -> 0 | AN20: =_xlfn.XLOOKUP(A20,'[1]31'!$A:$A,'[1]31'!$AR:$AR) -> 80 | AP20: =AO20+AN20 -> 80 | AQ20: =AP20-AR20 -> 0 | AR20: 80 | AS20: =SUM(AQ20/D20,0) -> #DIV/0! | AT20: 250 | AU20: =AT20-AR20 -> 170 | AW20: =ROUNDUP(I20*AS20,0) -> #DIV/0! | AX20: =ROUNDUP(H20*AS20,0) -> #DIV/0! | AY20: =ROUNDUP(J20*AS20,0) -> #DIV/0! | BB20: =AQ20-AW20-AX20-AY20 -> #DIV/0!
A21: ='ENTRY SHEET'!F21 -> OD09C5137 | B21: =_xlfn.XLOOKUP(A21,'[1]31'!$A:$A,'[1]31'!$C:$C) -> 17100.35 | C21: 17100.35 | D21: =C21-B21 -> 0 | E21: 12 | G21: 0 | Q21: =F21+G21+H21+I21+J21+K21+L21+M21+N21+O21+P21 -> 0 | R21: =_xlfn.XLOOKUP(A21,'[1]31'!$A:$A,'[1]31'!$S:$S) -> 131760.8 | S21: 131760.8 | T21: =S21-R21 -> 0 | Y21: =X21+W21+V21+U21 -> 0 | AG21: =Z21+AA21+AB21+AC21+AD21+AE21+AF21 -> 0 | AL21: =AH21+AI21 -> 0 | AM21: =AJ21+AK21 -> 0 | AN21: =_xlfn.XLOOKUP(A21,'[1]31'!$A:$A,'[1]31'!$AR:$AR) -> 70 | AP21: =AO21+AN21 -> 70 | AQ21: =AP21-AR21 -> 0 | AR21: 70 | AS21: =SUM(AQ21/D21,0) -> #DIV/0! | AT21: 250 | AU21: =AT21-AR21 -> 180 | AW21: =ROUNDUP(I21*AS21,0) -> #DIV/0! | AX21: =ROUNDUP(H21*AS21,0) -> #DIV/0! | AY21: =ROUNDUP(J21*AS21,0) -> #DIV/0! | BB21: =AQ21-AW21-AX21-AY21 -> #DIV/0!
A22: ='ENTRY SHEET'!F22 -> OD09C4623 | B22: =_xlfn.XLOOKUP(A22,'[1]31'!$A:$A,'[1]31'!$C:$C) -> 1457.5 | C22: 1457.5 | D22: =C22-B22 -> 0 | E22: 12 | G22: =D22-H22-I22 -> 0 | Q22: =F22+G22+H22+I22+J22+K22+L22+M22+N22+O22+P22 -> 0 | R22: =_xlfn.XLOOKUP(A22,'[1]31'!$A:$A,'[1]31'!$S:$S) -> 65563 | S22: 65563 | T22: =S22-R22 -> 0 | Y22: =X22+W22+V22+U22 -> 0 | AG22: =Z22+AA22+AB22+AC22+AD22+AE22+AF22 -> 0 | AL22: =AH22+AI22 -> 0 | AM22: =AJ22+AK22 -> 0 | AN22: =_xlfn.XLOOKUP(A22,'[1]31'!$A:$A,'[1]31'!$AR:$AR) -> 0 | AP22: =AO22+AN22 -> 0 | AQ22: =AP22-AR22 -> 0 | AS22: =SUM(AQ22/D22,0) -> #DIV/0! | AT22: 250 | AU22: =AT22-AR22 -> 250 | AW22: =ROUNDUP(I22*AS22,0) -> #DIV/0! | AX22: =ROUNDUP(H22*AS22,0) -> #DIV/0! | AY22: =ROUNDUP(J22*AS22,0) -> #DIV/0! | BB22: =AQ22-AW22-AX22-AY22 -> #DIV/0!
A23: ='ENTRY SHEET'!F23 -> OD09C4625 | B23: =_xlfn.XLOOKUP(A23,'[1]31'!$A:$A,'[1]31'!$C:$C) -> 24061.9 | C23: 24068.75 | D23: =C23-B23 -> 6.85 | E23: 12 | G23: 0 | H23: 2.15 | I23: 4.7 | Q23: =F23+G23+H23+I23+J23+K23+L23+M23+N23+O23+P23 -> 6.85 | R23: =_xlfn.XLOOKUP(A23,'[1]31'!$A:$A,'[1]31'!$S:$S) -> 88502.6 | S23: 88530.8 | T23: =S23-R23 -> 28.2 | Y23: =X23+W23+V23+U23 -> 0 | Z23: 8 | AB23: 3 | AG23: =Z23+AA23+AB23+AC23+AD23+AE23+AF23 -> 11 | AH23: 10 | AJ23: 303.97 | AL23: =AH23+AI23 -> 10 | AM23: =AJ23+AK23 -> 303.97 | AN23: =_xlfn.XLOOKUP(A23,'[1]31'!$A:$A,'[1]31'!$AR:$AR) -> 130 | AO23: 50 | AP23: =AO23+AN23 -> 180 | AQ23: =AP23-AR23 -> 40 | AR23: 140 | AS23: =SUM(AQ23/D23,0) -> 5.8394161 | AT23: 250 | AU23: =AT23-AR23 -> 110 | AW23: =ROUNDUP(I23*AS23,0) -> 28 | AX23: =ROUNDUP(H23*AS23,0) -> 13 | AY23: =ROUNDUP(J23*AS23,0) -> 0 | BB23: =AQ23-AW23-AX23-AY23 -> -1
A24: ='ENTRY SHEET'!F24 -> OD09C4823 | B24: =_xlfn.XLOOKUP(A24,'[1]31'!$A:$A,'[1]31'!$C:$C) -> 23965.45 | C24: 23971.3 | D24: =C24-B24 -> 5.85 | E24: 12 | G24: 0 | H24: 1.15 | I24: =5.85-1.15 -> 4.7 | Q24: =F24+G24+H24+I24+J24+K24+L24+M24+N24+O24+P24 -> 5.85 | R24: =_xlfn.XLOOKUP(A24,'[1]31'!$A:$A,'[1]31'!$S:$S) -> 146308 | S24: 146333.2 | T24: =S24-R24 -> 25.2 | Y24: =X24+W24+V24+U24 -> 0 | AB24: 4 | AG24: =Z24+AA24+AB24+AC24+AD24+AE24+AF24 -> 4 | AH24: 9 | AJ24: 280.01 | AL24: =AH24+AI24 -> 9 | AM24: =AJ24+AK24 -> 280.01 | AN24: =_xlfn.XLOOKUP(A24,'[1]31'!$A:$A,'[1]31'!$AR:$AR) -> 90 | AO24: 100 | AP24: =AO24+AN24 -> 190 | AQ24: =AP24-AR24 -> 20 | AR24: 170 | AS24: =SUM(AQ24/D24,0) -> 3.4188034 | AT24: 250 | AU24: =AT24-AR24 -> 80 | AW24: =ROUNDUP(I24*AS24,0) -> 17 | AX24: =ROUNDUP(H24*AS24,0) -> 4 | AY24: =ROUNDUP(J24*AS24,0) -> 0 | BB24: =AQ24-AW24-AX24-AY24 -> -1
A25: ='ENTRY SHEET'!F25 -> OD09C-4824 | B25: =_xlfn.XLOOKUP(A25,'[1]31'!$A:$A,'[1]31'!$C:$C) -> 17192.05 | C25: 17192.05 | D25: =C25-B25 -> 0 | E25: 12 | G25: =D25-H25-I25 -> 0 | Q25: =F25+G25+H25+I25+J25+K25+L25+M25+N25+O25+P25 -> 0 | R25: =_xlfn.XLOOKUP(A25,'[1]31'!$A:$A,'[1]31'!$S:$S) -> 110056.6 | S25: 110056.6 | T25: =S25-R25 -> 0 | Y25: =X25+W25+V25+U25 -> 0 | AG25: =Z25+AA25+AB25+AC25+AD25+AE25+AF25 -> 0 | AL25: =AH25+AI25 -> 0 | AM25: =AJ25+AK25 -> 0 | AN25: =_xlfn.XLOOKUP(A25,'[1]31'!$A:$A,'[1]31'!$AR:$AR) -> 175 | AP25: =AO25+AN25 -> 175 | AQ25: =AP25-AR25 -> 0 | AR25: 175 | AS25: =SUM(AQ25/D25,0) -> #DIV/0! | AT25: 250 | AU25: =AT25-AR25 -> 75 | AW25: =ROUNDUP(I25*AS25,0) -> #DIV/0! | AX25: =ROUNDUP(H25*AS25,0) -> #DIV/0! | AY25: =ROUNDUP(J25*AS25,0) -> #DIV/0! | BB25: =AQ25-AW25-AX25-AY25 -> #DIV/0!
A26: ='ENTRY SHEET'!F26 -> JH06H-3742 | B26: =_xlfn.XLOOKUP(A26,'[1]31'!$A:$A,'[1]31'!$C:$C) -> 18386 | C26: 18386 | D26: =C26-B26 -> 0 | E26: 12 | G26: =D26-H26-I26 -> 0 | Q26: =F26+G26+H26+I26+J26+K26+L26+M26+N26+O26+P26 -> 0 | R26: =_xlfn.XLOOKUP(A26,'[1]31'!$A:$A,'[1]31'!$S:$S) -> 0 | T26: =S26-R26 -> 0 | Y26: =X26+W26+V26+U26 -> 0 | AG26: =Z26+AA26+AB26+AC26+AD26+AE26+AF26 -> 0 | AL26: =AH26+AI26 -> 0 | AM26: =AJ26+AK26 -> 0 | AN26: =_xlfn.XLOOKUP(A26,'[1]31'!$A:$A,'[1]31'!$AR:$AR) -> 65 | AP26: =AO26+AN26 -> 65 | AQ26: =AP26-AR26 -> 0 | AR26: 65 | AS26: =SUM(AQ26/D26,0) -> #DIV/0! | AT26: 250 | AU26: =AT26-AR26 -> 185 | AW26: =ROUNDUP(I26*AS26,0) -> #DIV/0! | AX26: =ROUNDUP(H26*AS26,0) -> #DIV/0! | AY26: =ROUNDUP(J26*AS26,0) -> #DIV/0! | BB26: =AQ26-AW26-AX26-AY26 -> #DIV/0!
A27: ='ENTRY SHEET'!F27 -> OD09C-4879 | B27: =_xlfn.XLOOKUP(A27,'[1]31'!$A:$A,'[1]31'!$C:$C) -> 12980 | C27: 12980 | D27: =C27-B27 -> 0 | E27: 12 | G27: =D27-H27-I27 -> 0 | Q27: =F27+G27+H27+I27+J27+K27+L27+M27+N27+O27+P27 -> 0 | R27: =_xlfn.XLOOKUP(A27,'[1]31'!$A:$A,'[1]31'!$S:$S) -> 0 | T27: =S27-R27 -> 0 | Y27: =X27+W27+V27+U27 -> 0 | AG27: =Z27+AA27+AB27+AC27+AD27+AE27+AF27 -> 0 | AL27: =AH27+AI27 -> 0 | AM27: =AJ27+AK27 -> 0 | AN27: =_xlfn.XLOOKUP(A27,'[1]31'!$A:$A,'[1]31'!$AR:$AR) -> 85 | AP27: =AO27+AN27 -> 85 | AQ27: =AP27-AR27 -> 0 | AR27: 85 | AS27: =SUM(AQ27/D27,0) -> #DIV/0! | AT27: 250 | AU27: =AT27-AR27 -> 165 | AW27: =ROUNDUP(I27*AS27,0) -> #DIV/0! | AX27: =ROUNDUP(H27*AS27,0) -> #DIV/0! | AY27: =ROUNDUP(J27*AS27,0) -> #DIV/0! | BB27: =AQ27-AW27-AX27-AY27 -> #DIV/0!
A28: ='ENTRY SHEET'!F28 -> OD09C-1371 | B28: =_xlfn.XLOOKUP(A28,'[1]31'!$A:$A,'[1]31'!$C:$C) -> 11492 | C28: 11495 | D28: =C28-B28 -> 3 | E28: 12 | G28: =D28-H28-I28 -> 3 | Q28: =F28+G28+H28+I28+J28+K28+L28+M28+N28+O28+P28 -> 3 | R28: =_xlfn.XLOOKUP(A28,'[1]31'!$A:$A,'[1]31'!$S:$S) -> 137542 | S28: 137564 | T28: =S28-R28 -> 22 | V28: 7 | Y28: =X28+W28+V28+U28 -> 7 | AG28: =Z28+AA28+AB28+AC28+AD28+AE28+AF28 -> 0 | AL28: =AH28+AI28 -> 0 | AM28: =AJ28+AK28 -> 0 | AN28: =_xlfn.XLOOKUP(A28,'[1]31'!$A:$A,'[1]31'!$AR:$AR) -> 70 | AO28: 100 | AP28: =AO28+AN28 -> 170 | AQ28: =AP28-AR28 -> 30 | AR28: 140 | AS28: =SUM(AQ28/D28,0) -> 10 | AT28: 250 | AU28: =AT28-AR28 -> 110 | AW28: =ROUNDUP(I28*AS28,0) -> 0 | AX28: =ROUNDUP(H28*AS28,0) -> 0 | AY28: =ROUNDUP(J28*AS28,0) -> 0 | BB28: =AQ28-AW28-AX28-AY28 -> 30
A29: ='ENTRY SHEET'!F29 -> OD09C-4878 | B29: =_xlfn.XLOOKUP(A29,'[1]31'!$A:$A,'[1]31'!$C:$C) -> 0 | D29: =C29-B29 -> 0 | E29: 12 | G29: =D29-H29-I29 -> 0 | Q29: =F29+G29+H29+I29+J29+K29+L29+M29+N29+O29+P29 -> 0 | R29: =_xlfn.XLOOKUP(A29,'[1]31'!$A:$A,'[1]31'!$S:$S) -> 0 | T29: =S29-R29 -> 0 | Y29: =X29+W29+V29+U29 -> 0 | AG29: =Z29+AA29+AB29+AC29+AD29+AE29+AF29 -> 0 | AL29: =AH29+AI29 -> 0 | AM29: =AJ29+AK29 -> 0 | AN29: =_xlfn.XLOOKUP(A29,'[1]31'!$A:$A,'[1]31'!$AR:$AR) -> 0 | AP29: =AO29+AN29 -> 0 | AQ29: =AP29-AR29 -> 0 | AS29: =SUM(AQ29/D29,0) -> #DIV/0! | AT29: 250 | AU29: =AT29-AR29 -> 250 | AW29: =ROUNDUP(I29*AS29,0) -> #DIV/0! | AX29: =ROUNDUP(H29*AS29,0) -> #DIV/0! | AY29: =ROUNDUP(J29*AS29,0) -> #DIV/0! | BB29: =AQ29-AW29-AX29-AY29 -> #DIV/0!
A30: ='ENTRY SHEET'!F30 -> OD09C-8163 | B30: =_xlfn.XLOOKUP(A30,'[1]31'!$A:$A,'[1]31'!$C:$C) -> 13372.7 | C30: 13379.4 | D30: =C30-B30 -> 6.7 | E30: 12 | G30: =D30-H30-I30 -> 6.7 | Q30: =F30+G30+H30+I30+J30+K30+L30+M30+N30+O30+P30 -> 6.7 | R30: =_xlfn.XLOOKUP(A30,'[1]31'!$A:$A,'[1]31'!$S:$S) -> 61488 | S30: 61527 | T30: =S30-R30 -> 39 | U30: 3 | V30: 14 | Y30: =X30+W30+V30+U30 -> 17 | AG30: =Z30+AA30+AB30+AC30+AD30+AE30+AF30 -> 0 | AL30: =AH30+AI30 -> 0 | AM30: =AJ30+AK30 -> 0 | AN30: =_xlfn.XLOOKUP(A30,'[1]31'!$A:$A,'[1]31'!$AR:$AR) -> 140 | AO30: 50 | AP30: =AO30+AN30 -> 190 | AQ30: =AP30-AR30 -> 40 | AR30: 150 | AS30: =SUM(AQ30/D30,0) -> 5.9701493 | AT30: 250 | AU30: =AT30-AR30 -> 100 | AW30: =ROUNDUP(I30*AS30,0) -> 0 | AX30: =ROUNDUP(H30*AS30,0) -> 0 | AY30: =ROUNDUP(J30*AS30,0) -> 0 | BB30: =AQ30-AW30-AX30-AY30 -> 40
A31: ='ENTRY SHEET'!F31 -> OD09A-5106 | B31: =_xlfn.XLOOKUP(A31,'[1]31'!$A:$A,'[1]31'!$C:$C) -> 15049 | C31: 15058 | D31: =C31-B31 -> 9 | E31: 12 | G31: =D31-H31-I31 -> 9 | Q31: =F31+G31+H31+I31+J31+K31+L31+M31+N31+O31+P31 -> 9 | R31: =_xlfn.XLOOKUP(A31,'[1]31'!$A:$A,'[1]31'!$S:$S) -> 123070 | S31: 123109 | T31: =S31-R31 -> 39 | U31: 5 | V31: 8 | Y31: =X31+W31+V31+U31 -> 13 | AG31: =Z31+AA31+AB31+AC31+AD31+AE31+AF31 -> 0 | AL31: =AH31+AI31 -> 0 | AM31: =AJ31+AK31 -> 0 | AN31: =_xlfn.XLOOKUP(A31,'[1]31'!$A:$A,'[1]31'!$AR:$AR) -> 150 | AO31: 50 | AP31: =AO31+AN31 -> 200 | AQ31: =AP31-AR31 -> 50 | AR31: 150 | AS31: =SUM(AQ31/D31,0) -> 5.5555556 | AT31: 250 | AU31: =AT31-AR31 -> 100 | AW31: =ROUNDUP(I31*AS31,0) -> 0 | AX31: =ROUNDUP(H31*AS31,0) -> 0 | AY31: =ROUNDUP(J31*AS31,0) -> 0 | BB31: =AQ31-AW31-AX31-AY31 -> 50
A32: ='ENTRY SHEET'!F32 -> OD09C-8164 | B32: =_xlfn.XLOOKUP(A32,'[1]31'!$A:$A,'[1]31'!$C:$C) -> 10402.2 | C32: 10405.7 | D32: =C32-B32 -> 3.5 | E32: 12 | G32: =D32-H32-I32 -> 0.3 | H32: 3.2 | Q32: =F32+G32+H32+I32+J32+K32+L32+M32+N32+O32+P32 -> 3.5 | R32: =_xlfn.XLOOKUP(A32,'[1]31'!$A:$A,'[1]31'!$S:$S) -> 69740 | S32: 69760 | T32: =S32-R32 -> 20 | V32: 1 | Y32: =X32+W32+V32+U32 -> 1 | AD32: 6 | AG32: =Z32+AA32+AB32+AC32+AD32+AE32+AF32 -> 6 | AL32: =AH32+AI32 -> 0 | AM32: =AJ32+AK32 -> 0 | AN32: =_xlfn.XLOOKUP(A32,'[1]31'!$A:$A,'[1]31'!$AR:$AR) -> 100 | AO32: 100 | AP32: =AO32+AN32 -> 200 | AQ32: =AP32-AR32 -> 25 | AR32: 175 | AS32: =SUM(AQ32/D32,0) -> 7.1428571 | AT32: 250 | AU32: =AT32-AR32 -> 75 | AW32: =ROUNDUP(I32*AS32,0) -> 0 | AX32: =ROUNDUP(H32*AS32,0) -> 23 | AY32: =ROUNDUP(J32*AS32,0) -> 0 | BB32: =AQ32-AW32-AX32-AY32 -> 2
A33: ='ENTRY SHEET'!F33 -> OD09C-1373 | B33: =_xlfn.XLOOKUP(A33,'[1]31'!$A:$A,'[1]31'!$C:$C) -> 0 | D33: =C33-B33 -> 0 | E33: 12 | G33: =D33-H33-I33 -> 0 | Q33: =F33+G33+H33+I33+J33+K33+L33+M33+N33+O33+P33 -> 0 | R33: =_xlfn.XLOOKUP(A33,'[1]31'!$A:$A,'[1]31'!$S:$S) -> 0 | T33: =S33-R33 -> 0 | Y33: =X33+W33+V33+U33 -> 0 | AG33: =Z33+AA33+AB33+AC33+AD33+AE33+AF33 -> 0 | AL33: =AH33+AI33 -> 0 | AM33: =AJ33+AK33 -> 0 | AN33: =_xlfn.XLOOKUP(A33,'[1]31'!$A:$A,'[1]31'!$AR:$AR) -> 0 | AP33: =AO33+AN33 -> 0 | AQ33: =AP33-AR33 -> 0 | AS33: =SUM(AQ33/D33,0) -> #DIV/0! | AT33: 250 | AU33: =AT33-AR33 -> 250 | AW33: =ROUNDUP(I33*AS33,0) -> #DIV/0! | AX33: =ROUNDUP(H33*AS33,0) -> #DIV/0! | AY33: =ROUNDUP(J33*AS33,0) -> #DIV/0! | BB33: =AQ33-AW33-AX33-AY33 -> #DIV/0!
A34: ='ENTRY SHEET'!F34 -> OD09A-5666 | B34: =_xlfn.XLOOKUP(A34,'[1]31'!$A:$A,'[1]31'!$C:$C) -> 21853 | C34: 21859 | D34: =C34-B34 -> 6 | E34: 12 | G34: =D34-H34-I34 -> 0 | H34: 1 | I34: 5 | Q34: =F34+G34+H34+I34+J34+K34+L34+M34+N34+O34+P34 -> 6 | R34: =_xlfn.XLOOKUP(A34,'[1]31'!$A:$A,'[1]31'!$S:$S) -> 102060 | S34: 102092 | T34: =S34-R34 -> 32 | Y34: =X34+W34+V34+U34 -> 0 | AB34: 3 | AG34: =Z34+AA34+AB34+AC34+AD34+AE34+AF34 -> 3 | AH34: 11 | AJ34: 331.29 | AL34: =AH34+AI34 -> 11 | AM34: =AJ34+AK34 -> 331.29 | AN34: =_xlfn.XLOOKUP(A34,'[1]31'!$A:$A,'[1]31'!$AR:$AR) -> 140 | AO34: 60 | AP34: =AO34+AN34 -> 200 | AQ34: =AP34-AR34 -> 50 | AR34: 150 | AS34: =SUM(AQ34/D34,0) -> 8.3333333 | AT34: 250 | AU34: =AT34-AR34 -> 100 | AW34: =ROUNDUP(I34*AS34,0) -> 42 | AX34: =ROUNDUP(H34*AS34,0) -> 9 | AY34: =ROUNDUP(J34*AS34,0) -> 0 | BB34: =AQ34-AW34-AX34-AY34 -> -1
A35: ='ENTRY SHEET'!F35 -> OD09A-6059 | B35: =_xlfn.XLOOKUP(A35,'[1]31'!$A:$A,'[1]31'!$C:$C) -> 14031 | C35: 14039 | D35: =C35-B35 -> 8 | E35: 12 | G35: =D35-H35-I35 -> 5 | H35: 3 | Q35: =F35+G35+H35+I35+J35+K35+L35+M35+N35+O35+P35 -> 8 | R35: =_xlfn.XLOOKUP(A35,'[1]31'!$A:$A,'[1]31'!$S:$S) -> 91579 | S35: 91618 | T35: =S35-R35 -> 39 | V35: 9 | Y35: =X35+W35+V35+U35 -> 9 | AD35: 6 | AG35: =Z35+AA35+AB35+AC35+AD35+AE35+AF35 -> 6 | AL35: =AH35+AI35 -> 0 | AM35: =AJ35+AK35 -> 0 | AN35: =_xlfn.XLOOKUP(A35,'[1]31'!$A:$A,'[1]31'!$AR:$AR) -> 120 | AO35: 100 | AP35: =AO35+AN35 -> 220 | AQ35: =AP35-AR35 -> 40 | AR35: 180 | AS35: =SUM(AQ35/D35,0) -> 5 | AT35: 250 | AU35: =AT35-AR35 -> 70 | AW35: =ROUNDUP(I35*AS35,0) -> 0 | AX35: =ROUNDUP(H35*AS35,0) -> 15 | AY35: =ROUNDUP(J35*AS35,0) -> 0 | BB35: =AQ35-AW35-AX35-AY35 -> 25
A36: ='ENTRY SHEET'!F36 -> JH06H-9654 | B36: =_xlfn.XLOOKUP(A36,'[1]31'!$A:$A,'[1]31'!$C:$C) -> 0 | D36: 4 | E36: 12 | G36: =D36-H36-I36 -> 1.5 | H36: 2.5 | Q36: =F36+G36+H36+I36+J36+K36+L36+M36+N36+O36+P36 -> 4 | R36: =_xlfn.XLOOKUP(A36,'[1]31'!$A:$A,'[1]31'!$S:$S) -> 100651 | S36: 100702 | T36: =S36-R36 -> 51 | V36: 4 | Y36: =X36+W36+V36+U36 -> 4 | AD36: 5 | AG36: =Z36+AA36+AB36+AC36+AD36+AE36+AF36 -> 5 | AL36: =AH36+AI36 -> 0 | AM36: =AJ36+AK36 -> 0 | AN36: =_xlfn.XLOOKUP(A36,'[1]31'!$A:$A,'[1]31'!$AR:$AR) -> 220 | AO36: 50 | AP36: =AO36+AN36 -> 270 | AQ36: =AP36-AR36 -> 140 | AR36: 130 | AS36: =SUM(AQ36/D36,0) -> 35 | AT36: 250 | AU36: =AT36-AR36 -> 120 | AW36: =ROUNDUP(I36*AS36,0) -> 0 | AX36: =ROUNDUP(H36*AS36,0) -> 88 | AY36: =ROUNDUP(J36*AS36,0) -> 0 | BB36: =AQ36-AW36-AX36-AY36 -> 52
A37: ='ENTRY SHEET'!F37 -> OD09A-5105 | B37: =_xlfn.XLOOKUP(A37,'[1]31'!$A:$A,'[1]31'!$C:$C) -> 12596 | C37: 12604 | D37: =C37-B37 -> 8 | E37: 12 | G37: =D37-H37-I37 -> 8 | Q37: =F37+G37+H37+I37+J37+K37+L37+M37+N37+O37+P37 -> 8 | R37: =_xlfn.XLOOKUP(A37,'[1]31'!$A:$A,'[1]31'!$S:$S) -> 91212 | S37: 91262 | T37: =S37-R37 -> 50 | U37: 5 | V37: 14 | Y37: =X37+W37+V37+U37 -> 19 | AG37: =Z37+AA37+AB37+AC37+AD37+AE37+AF37 -> 0 | AL37: =AH37+AI37 -> 0 | AM37: =AJ37+AK37 -> 0 | AN37: =_xlfn.XLOOKUP(A37,'[1]31'!$A:$A,'[1]31'!$AR:$AR) -> 140 | AO37: 100 | AP37: =AO37+AN37 -> 240 | AQ37: =AP37-AR37 -> 65 | AR37: 175 | AS37: =SUM(AQ37/D37,0) -> 8.125 | AT37: 250 | AU37: =AT37-AR37 -> 75 | AW37: =ROUNDUP(I37*AS37,0) -> 0 | AX37: =ROUNDUP(H37*AS37,0) -> 0 | AY37: =ROUNDUP(J37*AS37,0) -> 0 | BB37: =AQ37-AW37-AX37-AY37 -> 65
A38: ='ENTRY SHEET'!F38 -> JH06G-4703 | B38: =_xlfn.XLOOKUP(A38,'[1]31'!$A:$A,'[1]31'!$C:$C) -> 8147 | C38: 8155 | D38: =C38-B38 -> 8 | E38: 12 | G38: =D38-H38-I38 -> 8 | Q38: =F38+G38+H38+I38+J38+K38+L38+M38+N38+O38+P38 -> 8 | R38: =_xlfn.XLOOKUP(A38,'[1]31'!$A:$A,'[1]31'!$S:$S) -> 95362 | S38: 95418 | T38: =S38-R38 -> 56 | U38: 6 | V38: 15 | Y38: =X38+W38+V38+U38 -> 21 | AG38: =Z38+AA38+AB38+AC38+AD38+AE38+AF38 -> 0 | AL38: =AH38+AI38 -> 0 | AM38: =AJ38+AK38 -> 0 | AN38: =_xlfn.XLOOKUP(A38,'[1]31'!$A:$A,'[1]31'!$AR:$AR) -> 160 | AO38: 50 | AP38: =AO38+AN38 -> 210 | AQ38: =AP38-AR38 -> 50 | AR38: 160 | AS38: =SUM(AQ38/D38,0) -> 6.25 | AT38: 250 | AU38: =AT38-AR38 -> 90 | AW38: =ROUNDUP(I38*AS38,0) -> 0 | AX38: =ROUNDUP(H38*AS38,0) -> 0 | AY38: =ROUNDUP(J38*AS38,0) -> 0 | BB38: =AQ38-AW38-AX38-AY38 -> 50
A39: ='ENTRY SHEET'!F39 -> JH06H-5348 | B39: =_xlfn.XLOOKUP(A39,'[1]31'!$A:$A,'[1]31'!$C:$C) -> 394.5 | C39: 402 | D39: =C39-B39 -> 7.5 | E39: 12 | G39: =D39-H39-I39 -> 4.5 | H39: 3 | Q39: =F39+G39+H39+I39+J39+K39+L39+M39+N39+O39+P39 -> 7.5 | R39: =_xlfn.XLOOKUP(A39,'[1]31'!$A:$A,'[1]31'!$S:$S) -> 122018 | S39: 122057 | T39: =S39-R39 -> 39 | V39: 9 | Y39: =X39+W39+V39+U39 -> 9 | AD39: 6 | AG39: =Z39+AA39+AB39+AC39+AD39+AE39+AF39 -> 6 | AL39: =AH39+AI39 -> 0 | AM39: =AJ39+AK39 -> 0 | AN39: =_xlfn.XLOOKUP(A39,'[1]31'!$A:$A,'[1]31'!$AR:$AR) -> 130 | AO39: 50 | AP39: =AO39+AN39 -> 180 | AQ39: =AP39-AR39 -> 40 | AR39: 140 | AS39: =SUM(AQ39/D39,0) -> 5.3333333 | AT39: 0 | AU39: =AT39-AR39 -> -140 | AW39: =ROUNDUP(I39*AS39,0) -> 0 | AX39: =ROUNDUP(H39*AS39,0) -> 16 | AY39: =ROUNDUP(J39*AS39,0) -> 0 | BB39: =AQ39-AW39-AX39-AY39 -> 24
A40: ='ENTRY SHEET'!F40 -> OD09K-5036 | B40: =_xlfn.XLOOKUP(A40,'[1]31'!$A:$A,'[1]31'!$C:$C) -> 13265 | C40: 13265 | D40: =C40-B40 -> 0 | E40: 12 | G40: =D40-H40-I40 -> 0 | Q40: =F40+G40+H40+I40+J40+K40+L40+M40+N40+O40+P40 -> 0 | R40: =_xlfn.XLOOKUP(A40,'[1]31'!$A:$A,'[1]31'!$S:$S) -> 92832 | S40: 92832 | T40: =S40-R40 -> 0 | Y40: =X40+W40+V40+U40 -> 0 | AG40: =Z40+AA40+AB40+AC40+AD40+AE40+AF40 -> 0 | AL40: =AH40+AI40 -> 0 | AM40: =AJ40+AK40 -> 0 | AN40: =_xlfn.XLOOKUP(A40,'[1]31'!$A:$A,'[1]31'!$AR:$AR) -> 145 | AP40: =AO40+AN40 -> 145 | AQ40: =AP40-AR40 -> 0 | AR40: 145 | AS40: =SUM(AQ40/D40,0) -> #DIV/0! | AT40: 0 | AU40: =AT40-AR40 -> -145 | AW40: =ROUNDUP(I40*AS40,0) -> #DIV/0! | AX40: =ROUNDUP(H40*AS40,0) -> #DIV/0! | AY40: =ROUNDUP(J40*AS40,0) -> #DIV/0! | BB40: =AQ40-AW40-AX40-AY40 -> #DIV/0!
...

Sheet 02
A1: ='ENTRY SHEET'!G1 -> DAILY REPORT OF APRIL-2026
R2: DATE: | S2: ='01'!S2+1 -> 46114
B3: HOUR METER | R3: KILO METER | U3: MINES TRIPS | Z3: REHANDLING C.PLANT | AH3: SIFTING TRIP | AN3: H.S.D REPORT | AV3: REMARKS | AW3: HSD Consumption Details
A4: VICHELE NO. | B4: OMR | C4: CMR | D4: TOTAL HOURS | E4: PLAN HRS | F4: Breakfast & Lunch hrs | G4: MINES RHS | H4: REHANDLING HRS | I4: SHIFTING HRS | J4: CRUSHER HRS | K4: SCREEN PLANT | L4: LOKO TRACK | M4: BREAKING HRS | N4: BREAKDOWN HRS | O4: Marching HRS | P4: Mining Development hrs | Q4: TOTAL HRS | R4: OMR | S4: CMR | T4: TOTAL KM | U4: ROM TRIPS | V4: OB TRIPS | W4: S.ORE | X4: BD | Y4: TOTAL TRIPS | Z4: ROM TRIP | AA4: 10\40 TRIP | AB4: FINES TRIP | AC4: LR TRIP | AD4: SUBGRADE TO CRUSHER | AE4: SCREEN TO CRUSHER | AF4: OB TRIPS | AG4: REHANDLING TRIP | AH4: 10\40 TRIP | AI4: FINES TRIP | AJ4: 10\40 MT | AK4: FINES MT | AL4: TOTAL SIFTING TRIP | AM4: TOTAL SIFTING TONES | AN4: OPENING BALANCE | AO4: ISSUE H.S.D | AP4: TOTAL H.S.D | AQ4: Diesel Consumption | AR4: CLOSING BALANCE | AS4: PER HRS CONS. | AT4: Tank capacity | AU4: Tanking Full Required | AW4: SHIFTING | AX4: Rehandling | AY4: NW | AZ4: LOKA | BA4: BHP | BB4: MINES | BC4: POWER
A5: ='ENTRY SHEET'!F5 -> VOLVO 300-2 | B5: ='01'!C5 -> 21964.1 | C5: 21964.1 | D5: =C5-B5 -> 0 | E5: 12 | G5: =D5-H5-I5-J5-K5-L5-M5-N5-O5-P5 -> 0 | Q5: =F5+G5+H5+I5+J5+K5+L5+M5+N5+O5+P5 -> 0 | Y5: =X5+W5+V5+U5 -> 0 | AG5: =Z5+AA5+AB5+AC5+AD5+AE5+AF5 -> 0 | AL5: =AH5+AI5 -> 0 | AM5: =AJ5+AK5 -> 0 | AN5: ='01'!AR5 -> 350 | AP5: =AO5+AN5 -> 350 | AQ5: =AP5-AR5 -> 0 | AR5: 350 | AS5: =AQ5/D5 -> #DIV/0! | AT5: ='01'!AT5 -> 470 | AU5: =AT5-AR5 -> 120 | AW5: =ROUNDUP(I5*AS5,0) -> #DIV/0! | AX5: =ROUNDUP(H5*AS5,0) -> #DIV/0! | AY5: =ROUNDUP(J5*AS5,0) -> #DIV/0! | BB5: =AQ5-AW5-AX5-AY5 -> #DIV/0!
A6: ='ENTRY SHEET'!F6 -> VOLVO-300-7 | B6: ='01'!C6 -> 17654.6 | C6: 17663.6 | D6: =C6-B6 -> 9 | E6: 12 | G6: =D6-H6-I6-J6-K6-L6-M6-N6-O6-P6 -> 3.5 | H6: =60.1-54.6 -> 5.5 | Q6: =F6+G6+H6+I6+J6+K6+L6+M6+N6+O6+P6 -> 9 | V6: 29 | X6: 2 | Y6: =X6+W6+V6+U6 -> 31 | AD6: 60 | AG6: =Z6+AA6+AB6+AC6+AD6+AE6+AF6 -> 60 | AL6: =AH6+AI6 -> 0 | AM6: =AJ6+AK6 -> 0 | AN6: ='01'!AR6 -> 135 | AO6: 215 | AP6: =AO6+AN6 -> 350 | AQ6: =AP6-AR6 -> 160 | AR6: 190 | AS6: =AQ6/D6 -> 17.777778 | AT6: ='01'!AT6 -> 470 | AU6: =AT6-AR6 -> 280 | AW6: =ROUNDUP(I6*AS6,0) -> 0 | AX6: =ROUNDUP(H6*AS6,0) -> 98 | AY6: =ROUNDUP(J6*AS6,0) -> 0 | BB6: =AQ6-AW6-AX6-AY6 -> 62
A7: ='ENTRY SHEET'!F7 -> HITACHI-350 | B7: ='01'!C7 -> 15791.9 | C7: 15801.3 | D7: =C7-B7 -> 9.4 | E7: 12 | G7: =D7-H7-I7-J7-K7-L7-M7-N7-O7-P7 -> 4 | H7: =801.3-795.9 -> 5.4 | Q7: =F7+G7+H7+I7+J7+K7+L7+M7+N7+O7+P7 -> 9.4 | V7: 25 | Y7: =X7+W7+V7+U7 -> 25 | AD7: 40 | AG7: =Z7+AA7+AB7+AC7+AD7+AE7+AF7 -> 40 | AL7: =AH7+AI7 -> 0 | AM7: =AJ7+AK7 -> 0 | AN7: ='01'!AR7 -> 372 | AO7: 258 | AP7: =AO7+AN7 -> 630 | AQ7: =AP7-AR7 -> 282 | AR7: 348 | AS7: =AQ7/D7 -> 30 | AT7: ='01'!AT7 -> 630 | AU7: =AT7-AR7 -> 282 | AW7: =ROUNDUP(I7*AS7,0) -> 0 | AX7: =ROUNDUP(H7*AS7,0) -> 163 | AY7: =ROUNDUP(J7*AS7,0) -> 0 | BB7: =AQ7-AW7-AX7-AY7 -> 119
A8: ='ENTRY SHEET'!F8 -> VOLVO-480 | B8: ='01'!C8 -> 0 | D8: 3 | E8: 12 | G8: =D8-H8-I8-J8-K8-L8-M8-N8-O8-P8 -> 3 | Q8: =F8+G8+H8+I8+J8+K8+L8+M8+N8+O8+P8 -> 3 | V8: 18 | Y8: =X8+W8+V8+U8 -> 18 | AG8: =Z8+AA8+AB8+AC8+AD8+AE8+AF8 -> 0 | AL8: =AH8+AI8 -> 0 | AM8: =AJ8+AK8 -> 0 | AN8: ='01'!AR8 -> 240 | AP8: =AO8+AN8 -> 240 | AQ8: =AP8-AR8 -> 90 | AR8: 150 | AS8: =AQ8/D8 -> 30 | AT8: ='01'!AT8 -> 650 | AU8: =AT8-AR8 -> 500 | AW8: =ROUNDUP(I8*AS8,0) -> 0 | AX8: =ROUNDUP(H8*AS8,0) -> 0 | AY8: =ROUNDUP(J8*AS8,0) -> 0 | BB8: =AQ8-AW8-AX8-AY8 -> 90
A9: ='ENTRY SHEET'!F9 -> KOMASTU-350 DMC | B9: ='01'!C9 -> 12582.8 | C9: 12592 | D9: =C9-B9 -> 9.2 | E9: 12 | G9: =D9-H9-I9-J9-K9-L9-M9-N9-O9-P9 -> 9.2 | Q9: =F9+G9+H9+I9+J9+K9+L9+M9+N9+O9+P9 -> 9.2 | U9: 40 | V9: 37 | Y9: =X9+W9+V9+U9 -> 77 | AG9: =Z9+AA9+AB9+AC9+AD9+AE9+AF9 -> 0 | AL9: =AH9+AI9 -> 0 | AM9: =AJ9+AK9 -> 0 | AN9: ='01'!AR9 -> 0 | AO9: 470 | AP9: =AO9+AN9 -> 470 | AQ9: =AP9-AR9 -> 470 | AS9: =AQ9/D9 -> 51.086957 | AT9: ='01'!AT9 -> 0 | AU9: =AT9-AR9 -> 0 | AW9: =ROUNDUP(I9*AS9,0) -> 0 | AX9: =ROUNDUP(H9*AS9,0) -> 0 | AY9: =ROUNDUP(J9*AS9,0) -> 0 | BB9: =AQ9-AW9-AX9-AY9 -> 470
A10: ='ENTRY SHEET'!F10 -> VOLVO-300(5) | B10: ='01'!C10 -> 0 | D10: =C10-B10 -> 0 | E10: 12 | G10: =D10-H10-I10-J10-K10-L10-M10-N10-O10-P10 -> 0 | Q10: =F10+G10+H10+I10+J10+K10+L10+M10+N10+O10+P10 -> 0 | Y10: =X10+W10+V10+U10 -> 0 | AG10: =Z10+AA10+AB10+AC10+AD10+AE10+AF10 -> 0 | AL10: =AH10+AI10 -> 0 | AM10: =AJ10+AK10 -> 0 | AN10: ='01'!AR10 -> 0 | AP10: =AO10+AN10 -> 0 | AQ10: =AP10-AR10 -> 0 | AS10: =AQ10/D10 -> #DIV/0! | AT10: ='01'!AT10 -> 0 | AU10: =AT10-AR10 -> 0 | AW10: =ROUNDUP(I10*AS10,0) -> #DIV/0! | AX10: =ROUNDUP(H10*AS10,0) -> #DIV/0! | AY10: =ROUNDUP(J10*AS10,0) -> #DIV/0! | BB10: =AQ10-AW10-AX10-AY10 -> #DIV/0!
A11: ='ENTRY SHEET'!F11 -> VOLVO-380 | B11: ='01'!C11 -> 0 | D11: =C11-B11 -> 0 | E11: 12 | G11: =D11-H11-I11-J11-K11-L11-M11-N11-O11-P11 -> 0 | Q11: =F11+G11+H11+I11+J11+K11+L11+M11+N11+O11+P11 -> 0 | Y11: =X11+W11+V11+U11 -> 0 | AG11: =Z11+AA11+AB11+AC11+AD11+AE11+AF11 -> 0 | AL11: =AH11+AI11 -> 0 | AM11: =AJ11+AK11 -> 0 | AN11: ='01'!AR11 -> 0 | AP11: =AO11+AN11 -> 0 | AQ11: =AP11-AR11 -> 0 | AS11: =AQ11/D11 -> #DIV/0! | AT11: ='01'!AT11 -> 0 | AU11: =AT11-AR11 -> 0 | AW11: =ROUNDUP(I11*AS11,0) -> #DIV/0! | AX11: =ROUNDUP(H11*AS11,0) -> #DIV/0! | AY11: =ROUNDUP(J11*AS11,0) -> #DIV/0! | BB11: =AQ11-AW11-AX11-AY11 -> #DIV/0!
A12: ='ENTRY SHEET'!F12 -> DOZZER D65E | B12: ='01'!C12 -> 2222.5 | C12: 2228.7 | D12: =C12-B12 -> 6.2 | E12: 12 | G12: =D12-H12-I12-J12-K12-L12-M12-N12-O12-P12 -> 6.2 | Q12: =F12+G12+H12+I12+J12+K12+L12+M12+N12+O12+P12 -> 6.2 | Y12: =X12+W12+V12+U12 -> 0 | AG12: =Z12+AA12+AB12+AC12+AD12+AE12+AF12 -> 0 | AL12: =AH12+AI12 -> 0 | AM12: =AJ12+AK12 -> 0 | AN12: ='01'!AR12 -> 200 | AP12: =AO12+AN12 -> 200 | AQ12: =AP12-AR12 -> 80 | AR12: 120 | AS12: =AQ12/D12 -> 12.903226 | AT12: ='01'!AT12 -> 350 | AU12: =AT12-AR12 -> 230 | AW12: =ROUNDUP(I12*AS12,0) -> 0 | AX12: =ROUNDUP(H12*AS12,0) -> 0 | AY12: =ROUNDUP(J12*AS12,0) -> 0 | BB12: =AQ12-AW12-AX12-AY12 -> 80
A13: ='ENTRY SHEET'!F13 -> BD 85 DOZER | B13: ='01'!C13 -> 228.3 | C13: 235.1 | D13: =C13-B13 -> 6.8 | E13: 12 | G13: =D13-H13-I13-J13-K13-L13-M13-N13-O13-P13 -> 6.8 | Q13: =F13+G13+H13+I13+J13+K13+L13+M13+N13+O13+P13 -> 6.8 | Y13: =X13+W13+V13+U13 -> 0 | AG13: =Z13+AA13+AB13+AC13+AD13+AE13+AF13 -> 0 | AL13: =AH13+AI13 -> 0 | AM13: =AJ13+AK13 -> 0 | AN13: ='01'!AR13 -> 185 | AO13: 200 | AP13: =AO13+AN13 -> 385 | AQ13: =AP13-AR13 -> 100 | AR13: 285 | AS13: =AQ13/D13 -> 14.705882 | AT13: ='01'!AT13 -> 350 | AU13: =AT13-AR13 -> 65 | AW13: =ROUNDUP(I13*AS13,0) -> 0 | AX13: =ROUNDUP(H13*AS13,0) -> 0 | AY13: =ROUNDUP(J13*AS13,0) -> 0 | BB13: =AQ13-AW13-AX13-AY13 -> 100
A14: ='ENTRY SHEET'!F14 -> KOBELCO-380 DMCS | B14: ='01'!C14 -> 0 | D14: =C14-B14 -> 0 | E14: 12 | G14: =D14-H14-I14-J14-K14-L14-M14-N14-O14-P14 -> 0 | Q14: =F14+G14+H14+I14+J14+K14+L14+M14+N14+O14+P14 -> 0 | Y14: =X14+W14+V14+U14 -> 0 | AG14: =Z14+AA14+AB14+AC14+AD14+AE14+AF14 -> 0 | AL14: =AH14+AI14 -> 0 | AM14: =AJ14+AK14 -> 0 | AN14: ='01'!AR14 -> 0 | AP14: =AO14+AN14 -> 0 | AQ14: =AP14-AR14 -> 0 | AS14: =AQ14/D14 -> #DIV/0! | AT14: ='01'!AT14 -> 350 | AU14: =AT14-AR14 -> 350 | AW14: =ROUNDUP(I14*AS14,0) -> #DIV/0! | AX14: =ROUNDUP(H14*AS14,0) -> #DIV/0! | AY14: =ROUNDUP(J14*AS14,0) -> #DIV/0! | BB14: =AQ14-AW14-AX14-AY14 -> #DIV/0!
A15: ='ENTRY SHEET'!F15 -> GRADER OD09P-1732 | B15: ='01'!C15 -> 4551.5 | C15: 4551.5 | D15: =C15-B15 -> 0 | E15: 12 | G15: =D15-H15-I15-J15-K15-L15-M15-N15-O15-P15 -> 0 | Q15: =F15+G15+H15+I15+J15+K15+L15+M15+N15+O15+P15 -> 0 | Y15: =X15+W15+V15+U15 -> 0 | AG15: =Z15+AA15+AB15+AC15+AD15+AE15+AF15 -> 0 | AL15: =AH15+AI15 -> 0 | AM15: =AJ15+AK15 -> 0 | AN15: ='01'!AR15 -> 70 | AP15: =AO15+AN15 -> 70 | AQ15: =AP15-AR15 -> 0 | AR15: 70 | AS15: =AQ15/D15 -> #DIV/0! | AT15: ='01'!AT15 -> 350 | AU15: =AT15-AR15 -> 280 | AW15: =ROUNDUP(I15*AS15,0) -> #DIV/0! | AX15: =ROUNDUP(H15*AS15,0) -> #DIV/0! | AY15: =ROUNDUP(J15*AS15,0) -> #DIV/0! | BB15: =AQ15-AW15-AX15-AY15 -> #DIV/0!
A16: ='ENTRY SHEET'!F16 -> 0 | B16: ='01'!C16 -> 0 | C16: 0 | D16: =C16-B16 -> 0 | E16: 12 | Q16: =F16+G16+H16+I16+J16+K16+L16+M16+N16+O16+P16 -> 0 | Y16: =X16+W16+V16+U16 -> 0 | AG16: =Z16+AA16+AB16+AC16+AD16+AE16+AF16 -> 0 | AL16: =AH16+AI16 -> 0 | AM16: =AJ16+AK16 -> 0 | AN16: ='01'!AR16 -> 0 | AP16: =AO16+AN16 -> 0 | AQ16: =AP16-AR16 -> 0 | AS16: =AQ16/D16 -> #DIV/0! | AT16: ='01'!AT16 -> 0 | AU16: =AT16-AR16 -> 0 | AW16: =ROUNDUP(I16*AS16,0) -> #DIV/0! | AX16: =ROUNDUP(H16*AS16,0) -> #DIV/0! | AY16: =ROUNDUP(J16*AS16,0) -> #DIV/0! | BB16: =AQ16-AW16-AX16-AY16 -> #DIV/0!
A17: ='ENTRY SHEET'!F17 -> OD09C-1962 | B17: ='01'!C17 -> 20692.6 | C17: 20692.6 | D17: =C17-B17 -> 0 | E17: 12 | G17: =D17-H17-I17 -> 0 | Q17: =F17+G17+H17+I17+J17+K17+L17+M17+N17+O17+P17 -> 0 | R17: ='01'!S17 -> 156139.3 | S17: 156139.3 | T17: =S17-R17 -> 0 | Y17: =X17+W17+V17+U17 -> 0 | AG17: =Z17+AA17+AB17+AC17+AD17+AE17+AF17 -> 0 | AL17: =AH17+AI17 -> 0 | AM17: =AJ17+AK17 -> 0 | AN17: ='01'!AR17 -> 115 | AP17: =AO17+AN17 -> 115 | AQ17: =AP17-AR17 -> 0 | AR17: 115 | AS17: =AQ17/D17 -> #DIV/0! | AT17: ='01'!AT17 -> 250 | AU17: =AT17-AR17 -> 135 | AW17: =ROUNDUP(I17*AS17,0) -> #DIV/0! | AX17: =ROUNDUP(H17*AS17,0) -> #DIV/0! | AY17: =ROUNDUP(J17*AS17,0) -> #DIV/0! | BB17: =AQ17-AW17-AX17-AY17 -> #DIV/0!
A18: ='ENTRY SHEET'!F18 -> OD09C-1964 | B18: ='01'!C18 -> 14393 | C18: 14395.05 | D18: =C18-B18 -> 2.05 | E18: 12 | G18: =D18-H18-I18 -> 2.05 | Q18: =F18+G18+H18+I18+J18+K18+L18+M18+N18+O18+P18 -> 2.05 | R18: ='01'!S18 -> 152484 | S18: 152493.9 | T18: =S18-R18 -> 9.9 | V18: 3 | Y18: =X18+W18+V18+U18 -> 3 | AG18: =Z18+AA18+AB18+AC18+AD18+AE18+AF18 -> 0 | AL18: =AH18+AI18 -> 0 | AM18: =AJ18+AK18 -> 0 | AN18: ='01'!AR18 -> 140 | AP18: =AO18+AN18 -> 140 | AQ18: =AP18-AR18 -> 30 | AR18: 110 | AS18: =AQ18/D18 -> 14.634146 | AT18: ='01'!AT18 -> 250 | AU18: =AT18-AR18 -> 140 | AW18: =ROUNDUP(I18*AS18,0) -> 0 | AX18: =ROUNDUP(H18*AS18,0) -> 0 | AY18: =ROUNDUP(J18*AS18,0) -> 0 | BB18: =AQ18-AW18-AX18-AY18 -> 30
A19: ='ENTRY SHEET'!F19 -> OD09C1965 | B19: ='01'!C19 -> 16565.8 | C19: 16565.8 | D19: =C19-B19 -> 0 | E19: 12 | G19: =D19-H19-I19 -> 0 | Q19: =F19+G19+H19+I19+J19+K19+L19+M19+N19+O19+P19 -> 0 | R19: ='01'!S19 -> 166053.3 | S19: 166053.3 | T19: =S19-R19 -> 0 | Y19: =X19+W19+V19+U19 -> 0 | AG19: =Z19+AA19+AB19+AC19+AD19+AE19+AF19 -> 0 | AL19: =AH19+AI19 -> 0 | AM19: =AJ19+AK19 -> 0 | AN19: ='01'!AR19 -> 0 | AP19: =AO19+AN19 -> 0 | AQ19: =AP19-AR19 -> 0 | AS19: =AQ19/D19 -> #DIV/0! | AT19: ='01'!AT19 -> 250 | AU19: =AT19-AR19 -> 250 | AW19: =ROUNDUP(I19*AS19,0) -> #DIV/0! | AX19: =ROUNDUP(H19*AS19,0) -> #DIV/0! | AY19: =ROUNDUP(J19*AS19,0) -> #DIV/0! | BB19: =AQ19-AW19-AX19-AY19 -> #DIV/0!
A20: ='ENTRY SHEET'!F20 -> ODO9C5136 | B20: ='01'!C20 -> 17052.5 | C20: 17052.5 | D20: =C20-B20 -> 0 | E20: 12 | G20: =D20-H20-I20 -> 0 | Q20: =F20+G20+H20+I20+J20+K20+L20+M20+N20+O20+P20 -> 0 | R20: ='01'!S20 -> 125216 | S20: 125216 | T20: =S20-R20 -> 0 | Y20: =X20+W20+V20+U20 -> 0 | AG20: =Z20+AA20+AB20+AC20+AD20+AE20+AF20 -> 0 | AL20: =AH20+AI20 -> 0 | AM20: =AJ20+AK20 -> 0 | AN20: ='01'!AR20 -> 80 | AP20: =AO20+AN20 -> 80 | AQ20: =AP20-AR20 -> 0 | AR20: 80 | AS20: =AQ20/D20 -> #DIV/0! | AT20: ='01'!AT20 -> 250 | AU20: =AT20-AR20 -> 170 | AW20: =ROUNDUP(I20*AS20,0) -> #DIV/0! | AX20: =ROUNDUP(H20*AS20,0) -> #DIV/0! | AY20: =ROUNDUP(J20*AS20,0) -> #DIV/0! | BB20: =AQ20-AW20-AX20-AY20 -> #DIV/0!
A21: ='ENTRY SHEET'!F21 -> OD09C5137 | B21: ='01'!C21 -> 17100.35 | C21: 17100.35 | D21: =C21-B21 -> 0 | E21: 12 | G21: 0 | Q21: =F21+G21+H21+I21+J21+K21+L21+M21+N21+O21+P21 -> 0 | R21: ='01'!S21 -> 131760.8 | S21: 131760.8 | T21: =S21-R21 -> 0 | Y21: =X21+W21+V21+U21 -> 0 | AG21: =Z21+AA21+AB21+AC21+AD21+AE21+AF21 -> 0 | AL21: =AH21+AI21 -> 0 | AM21: =AJ21+AK21 -> 0 | AN21: ='01'!AR21 -> 70 | AP21: =AO21+AN21 -> 70 | AQ21: =AP21-AR21 -> 0 | AR21: 70 | AS21: =AQ21/D21 -> #DIV/0! | AT21: ='01'!AT21 -> 250 | AU21: =AT21-AR21 -> 180 | AW21: =ROUNDUP(I21*AS21,0) -> #DIV/0! | AX21: =ROUNDUP(H21*AS21,0) -> #DIV/0! | AY21: =ROUNDUP(J21*AS21,0) -> #DIV/0! | BB21: =AQ21-AW21-AX21-AY21 -> #DIV/0!
A22: ='ENTRY SHEET'!F22 -> OD09C4623 | B22: ='01'!C22 -> 1457.5 | C22: 1457.5 | D22: =C22-B22 -> 0 | E22: 12 | G22: =D22-H22-I22 -> 0 | Q22: =F22+G22+H22+I22+J22+K22+L22+M22+N22+O22+P22 -> 0 | R22: ='01'!S22 -> 65563 | S22: 65563 | T22: =S22-R22 -> 0 | Y22: =X22+W22+V22+U22 -> 0 | AG22: =Z22+AA22+AB22+AC22+AD22+AE22+AF22 -> 0 | AL22: =AH22+AI22 -> 0 | AM22: =AJ22+AK22 -> 0 | AN22: ='01'!AR22 -> 0 | AP22: =AO22+AN22 -> 0 | AQ22: =AP22-AR22 -> 0 | AS22: =AQ22/D22 -> #DIV/0! | AT22: ='01'!AT22 -> 250 | AU22: =AT22-AR22 -> 250 | AW22: =ROUNDUP(I22*AS22,0) -> #DIV/0! | AX22: =ROUNDUP(H22*AS22,0) -> #DIV/0! | AY22: =ROUNDUP(J22*AS22,0) -> #DIV/0! | BB22: =AQ22-AW22-AX22-AY22 -> #DIV/0!
A23: ='ENTRY SHEET'!F23 -> OD09C4625 | B23: ='01'!C23 -> 24068.75 | C23: 24073.2 | D23: =C23-B23 -> 4.45 | E23: 12 | G23: =D23-H23-I23 -> -0.15 | I23: 4.6 | Q23: =F23+G23+H23+I23+J23+K23+L23+M23+N23+O23+P23 -> 4.45 | R23: ='01'!S23 -> 88530.8 | S23: 88551.5 | T23: =S23-R23 -> 20.7 | Y23: =X23+W23+V23+U23 -> 0 | AG23: =Z23+AA23+AB23+AC23+AD23+AE23+AF23 -> 0 | AH23: 3 | AJ23: 90.72 | AL23: =AH23+AI23 -> 3 | AM23: =AJ23+AK23 -> 90.72 | AN23: ='01'!AR23 -> 140 | AP23: =AO23+AN23 -> 140 | AQ23: =AP23-AR23 -> 40 | AR23: 100 | AS23: =AQ23/D23 -> 8.988764 | AT23: ='01'!AT23 -> 250 | AU23: =AT23-AR23 -> 150 | AW23: =ROUNDUP(I23*AS23,0) -> 42 | AX23: =ROUNDUP(H23*AS23,0) -> 0 | AY23: =ROUNDUP(J23*AS23,0) -> 0 | BB23: =AQ23-AW23-AX23-AY23 -> -2
A24: ='ENTRY SHEET'!F24 -> OD09C4823 | B24: ='01'!C24 -> 23971.3 | C24: 23975.45 | D24: =C24-B24 -> 4.15 | E24: 12 | G24: =D24-H24-I24 -> -0.05 | H24: 1.05 | I24: 3.15 | Q24: =F24+G24+H24+I24+J24+K24+L24+M24+N24+O24+P24 -> 4.15 | R24: ='01'!S24 -> 146333.2 | S24: 146345.7 | T24: =S24-R24 -> 12.5 | Y24: =X24+W24+V24+U24 -> 0 | AB24: 7 | AG24: =Z24+AA24+AB24+AC24+AD24+AE24+AF24 -> 7 | AH24: 2 | AJ24: 62.52 | AL24: =AH24+AI24 -> 2 | AM24: =AJ24+AK24 -> 62.52 | AN24: ='01'!AR24 -> 170 | AP24: =AO24+AN24 -> 170 | AQ24: =AP24-AR24 -> 20 | AR24: 150 | AS24: =AQ24/D24 -> 4.8192771 | AT24: ='01'!AT24 -> 250 | AU24: =AT24-AR24 -> 100 | AW24: =ROUNDUP(I24*AS24,0) -> 16 | AX24: =ROUNDUP(H24*AS24,0) -> 6 | AY24: =ROUNDUP(J24*AS24,0) -> 0 | BB24: =AQ24-AW24-AX24-AY24 -> -2
A25: ='ENTRY SHEET'!F25 -> OD09C-4824 | B25: ='01'!C25 -> 17192.05 | C25: 17192.05 | D25: =C25-B25 -> 0 | E25: 12 | G25: =D25-H25-I25 -> 0 | Q25: =F25+G25+H25+I25+J25+K25+L25+M25+N25+O25+P25 -> 0 | R25: ='01'!S25 -> 110056.6 | S25: 110056.6 | T25: =S25-R25 -> 0 | Y25: =X25+W25+V25+U25 -> 0 | AG25: =Z25+AA25+AB25+AC25+AD25+AE25+AF25 -> 0 | AL25: =AH25+AI25 -> 0 | AM25: =AJ25+AK25 -> 0 | AN25: ='01'!AR25 -> 175 | AP25: =AO25+AN25 -> 175 | AQ25: =AP25-AR25 -> 0 | AR25: 175 | AS25: =AQ25/D25 -> #DIV/0! | AT25: ='01'!AT25 -> 250 | AU25: =AT25-AR25 -> 75 | AW25: =ROUNDUP(I25*AS25,0) -> #DIV/0! | AX25: =ROUNDUP(H25*AS25,0) -> #DIV/0! | AY25: =ROUNDUP(J25*AS25,0) -> #DIV/0! | BB25: =AQ25-AW25-AX25-AY25 -> #DIV/0!
A26: ='ENTRY SHEET'!F26 -> JH06H-3742 | B26: ='01'!C26 -> 18386 | D26: 8.5 | E26: 12 | G26: =D26-H26-I26 -> 0 | H26: =8.5 -> 8.5 | Q26: =F26+G26+H26+I26+J26+K26+L26+M26+N26+O26+P26 -> 8.5 | R26: ='01'!S26 -> 0 | T26: =S26-R26 -> 0 | Y26: =X26+W26+V26+U26 -> 0 | AD26: 20 | AG26: =Z26+AA26+AB26+AC26+AD26+AE26+AF26 -> 20 | AL26: =AH26+AI26 -> 0 | AM26: =AJ26+AK26 -> 0 | AN26: ='01'!AR26 -> 65 | AO26: 100 | AP26: =AO26+AN26 -> 165 | AQ26: =AP26-AR26 -> 55 | AR26: 110 | AS26: =AQ26/D26 -> 6.4705882 | AT26: ='01'!AT26 -> 250 | AU26: =AT26-AR26 -> 140 | AW26: =ROUNDUP(I26*AS26,0) -> 0 | AX26: =ROUNDUP(H26*AS26,0) -> 55 | AY26: =ROUNDUP(J26*AS26,0) -> 0 | BB26: =AQ26-AW26-AX26-AY26 -> 0
A27: ='ENTRY SHEET'!F27 -> OD09C-4879 | B27: ='01'!C27 -> 12980 | C27: 12984 | D27: =C27-B27 -> 4 | E27: 12 | G27: =D27-H27-I27 -> 0 | H27: =984-980 -> 4 | Q27: =F27+G27+H27+I27+J27+K27+L27+M27+N27+O27+P27 -> 4 | R27: ='01'!S27 -> 0 | T27: =S27-R27 -> 0 | Y27: =X27+W27+V27+U27 -> 0 | AD27: 6 | AG27: =Z27+AA27+AB27+AC27+AD27+AE27+AF27 -> 6 | AL27: =AH27+AI27 -> 0 | AM27: =AJ27+AK27 -> 0 | AN27: ='01'!AR27 -> 85 | AP27: =AO27+AN27 -> 85 | AQ27: =AP27-AR27 -> 20 | AR27: 65 | AS27: =AQ27/D27 -> 5 | AT27: ='01'!AT27 -> 250 | AU27: =AT27-AR27 -> 185 | AW27: =ROUNDUP(I27*AS27,0) -> 0 | AX27: =ROUNDUP(H27*AS27,0) -> 20 | AY27: =ROUNDUP(J27*AS27,0) -> 0 | BB27: =AQ27-AW27-AX27-AY27 -> 0
A28: ='ENTRY SHEET'!F28 -> OD09C-1371 | B28: ='01'!C28 -> 11495 | C28: 11498 | D28: =C28-B28 -> 3 | E28: 12 | G28: =D28-H28-I28 -> 3 | Q28: =F28+G28+H28+I28+J28+K28+L28+M28+N28+O28+P28 -> 3 | R28: ='01'!S28 -> 137564 | S28: 137577 | T28: =S28-R28 -> 13 | V28: 2 | Y28: =X28+W28+V28+U28 -> 2 | AG28: =Z28+AA28+AB28+AC28+AD28+AE28+AF28 -> 0 | AL28: =AH28+AI28 -> 0 | AM28: =AJ28+AK28 -> 0 | AN28: ='01'!AR28 -> 140 | AO28: 50 | AP28: =AO28+AN28 -> 190 | AQ28: =AP28-AR28 -> 20 | AR28: 170 | AS28: =AQ28/D28 -> 6.6666667 | AT28: ='01'!AT28 -> 250 | AU28: =AT28-AR28 -> 80 | AW28: =ROUNDUP(I28*AS28,0) -> 0 | AX28: =ROUNDUP(H28*AS28,0) -> 0 | AY28: =ROUNDUP(J28*AS28,0) -> 0 | BB28: =AQ28-AW28-AX28-AY28 -> 20
A29: ='ENTRY SHEET'!F29 -> OD09C-4878 | B29: ='01'!C29 -> 0 | D29: =C29-B29 -> 0 | E29: 12 | G29: =D29-H29-I29 -> 0 | Q29: =F29+G29+H29+I29+J29+K29+L29+M29+N29+O29+P29 -> 0 | R29: ='01'!S29 -> 0 | T29: =S29-R29 -> 0 | Y29: =X29+W29+V29+U29 -> 0 | AG29: =Z29+AA29+AB29+AC29+AD29+AE29+AF29 -> 0 | AL29: =AH29+AI29 -> 0 | AM29: =AJ29+AK29 -> 0 | AN29: ='01'!AR29 -> 0 | AP29: =AO29+AN29 -> 0 | AQ29: =AP29-AR29 -> 0 | AS29: =AQ29/D29 -> #DIV/0! | AT29: ='01'!AT29 -> 250 | AU29: =AT29-AR29 -> 250 | AW29: =ROUNDUP(I29*AS29,0) -> #DIV/0! | AX29: =ROUNDUP(H29*AS29,0) -> #DIV/0! | AY29: =ROUNDUP(J29*AS29,0) -> #DIV/0! | BB29: =AQ29-AW29-AX29-AY29 -> #DIV/0!
A30: ='ENTRY SHEET'!F30 -> OD09C-8163 | B30: ='01'!C30 -> 13379.4 | C30: 13382 | D30: =C30-B30 -> 2.6 | E30: 12 | G30: =D30-H30-I30 -> 2.6 | Q30: =F30+G30+H30+I30+J30+K30+L30+M30+N30+O30+P30 -> 2.6 | R30: ='01'!S30 -> 61527 | S30: 61539 | T30: =S30-R30 -> 12 | V30: 3 | Y30: =X30+W30+V30+U30 -> 3 | AG30: =Z30+AA30+AB30+AC30+AD30+AE30+AF30 -> 0 | AL30: =AH30+AI30 -> 0 | AM30: =AJ30+AK30 -> 0 | AN30: ='01'!AR30 -> 150 | AP30: =AO30+AN30 -> 150 | AQ30: =AP30-AR30 -> 0 | AR30: 150 | AS30: =AQ30/D30 -> 0 | AT30: ='01'!AT30 -> 250 | AU30: =AT30-AR30 -> 100 | AW30: =ROUNDUP(I30*AS30,0) -> 0 | AX30: =ROUNDUP(H30*AS30,0) -> 0 | AY30: =ROUNDUP(J30*AS30,0) -> 0 | BB30: =AQ30-AW30-AX30-AY30 -> 0
A31: ='ENTRY SHEET'!F31 -> OD09A-5106 | B31: ='01'!C31 -> 15058 | C31: 15061 | D31: =C31-B31 -> 3 | E31: 12 | G31: =D31-H31-I31 -> 3 | Q31: =F31+G31+H31+I31+J31+K31+L31+M31+N31+O31+P31 -> 3 | R31: ='01'!S31 -> 123109 | S31: 123132 | T31: =S31-R31 -> 23 | V31: 3 | X31: 1 | Y31: =X31+W31+V31+U31 -> 4 | AG31: =Z31+AA31+AB31+AC31+AD31+AE31+AF31 -> 0 | AL31: =AH31+AI31 -> 0 | AM31: =AJ31+AK31 -> 0 | AN31: ='01'!AR31 -> 150 | AP31: =AO31+AN31 -> 150 | AQ31: =AP31-AR31 -> 30 | AR31: 120 | AS31: =AQ31/D31 -> 10 | AT31: ='01'!AT31 -> 250 | AU31: =AT31-AR31 -> 130 | AW31: =ROUNDUP(I31*AS31,0) -> 0 | AX31: =ROUNDUP(H31*AS31,0) -> 0 | AY31: =ROUNDUP(J31*AS31,0) -> 0 | BB31: =AQ31-AW31-AX31-AY31 -> 30
A32: ='ENTRY SHEET'!F32 -> OD09C-8164 | B32: ='01'!C32 -> 10405.7 | C32: 10406.7 | D32: =C32-B32 -> 1 | E32: 12 | G32: =D32-H32-I32 -> 1 | Q32: =F32+G32+H32+I32+J32+K32+L32+M32+N32+O32+P32 -> 1 | R32: ='01'!S32 -> 69760 | S32: 69764 | T32: =S32-R32 -> 4 | V32: 1 | Y32: =X32+W32+V32+U32 -> 1 | AG32: =Z32+AA32+AB32+AC32+AD32+AE32+AF32 -> 0 | AL32: =AH32+AI32 -> 0 | AM32: =AJ32+AK32 -> 0 | AN32: ='01'!AR32 -> 175 | AP32: =AO32+AN32 -> 175 | AQ32: =AP32-AR32 -> 5 | AR32: 170 | AS32: =AQ32/D32 -> 5 | AT32: ='01'!AT32 -> 250 | AU32: =AT32-AR32 -> 80 | AW32: =ROUNDUP(I32*AS32,0) -> 0 | AX32: =ROUNDUP(H32*AS32,0) -> 0 | AY32: =ROUNDUP(J32*AS32,0) -> 0 | BB32: =AQ32-AW32-AX32-AY32 -> 5
A33: ='ENTRY SHEET'!F33 -> OD09C-1373 | B33: ='01'!C33 -> 0 | D33: =C33-B33 -> 0 | E33: 12 | G33: =D33-H33-I33 -> 0 | Q33: =F33+G33+H33+I33+J33+K33+L33+M33+N33+O33+P33 -> 0 | R33: ='01'!S33 -> 0 | T33: =S33-R33 -> 0 | Y33: =X33+W33+V33+U33 -> 0 | AG33: =Z33+AA33+AB33+AC33+AD33+AE33+AF33 -> 0 | AL33: =AH33+AI33 -> 0 | AM33: =AJ33+AK33 -> 0 | AN33: ='01'!AR33 -> 0 | AP33: =AO33+AN33 -> 0 | AQ33: =AP33-AR33 -> 0 | AS33: =AQ33/D33 -> #DIV/0! | AT33: ='01'!AT33 -> 250 | AU33: =AT33-AR33 -> 250 | AW33: =ROUNDUP(I33*AS33,0) -> #DIV/0! | AX33: =ROUNDUP(H33*AS33,0) -> #DIV/0! | AY33: =ROUNDUP(J33*AS33,0) -> #DIV/0! | BB33: =AQ33-AW33-AX33-AY33 -> #DIV/0!
A34: ='ENTRY SHEET'!F34 -> OD09A-5666 | B34: ='01'!C34 -> 21859 | C34: 21864 | D34: =C34-B34 -> 5 | E34: 12 | G34: =D34-H34-I34 -> 1 | H34: 3 | I34: 1 | Q34: =F34+G34+H34+I34+J34+K34+L34+M34+N34+O34+P34 -> 5 | R34: ='01'!S34 -> 102092 | S34: 102115 | T34: =S34-R34 -> 23 | V34: 3 | Y34: =X34+W34+V34+U34 -> 3 | AB34: 1 | AC34: 3 | AG34: =Z34+AA34+AB34+AC34+AD34+AE34+AF34 -> 4 | AH34: 2 | AJ34: 60.74 | AL34: =AH34+AI34 -> 2 | AM34: =AJ34+AK34 -> 60.74 | AN34: ='01'!AR34 -> 150 | AP34: =AO34+AN34 -> 150 | AQ34: =AP34-AR34 -> 30 | AR34: 120 | AS34: =AQ34/D34 -> 6 | AT34: ='01'!AT34 -> 250 | AU34: =AT34-AR34 -> 130 | AW34: =ROUNDUP(I34*AS34,0) -> 6 | AX34: =ROUNDUP(H34*AS34,0) -> 18 | AY34: =ROUNDUP(J34*AS34,0) -> 0 | BB34: =AQ34-AW34-AX34-AY34 -> 6
A35: ='ENTRY SHEET'!F35 -> OD09A-6059 | B35: ='01'!C35 -> 14039 | C35: 14046 | D35: =C35-B35 -> 7 | E35: 12 | G35: =D35-H35-I35 -> 3 | H35: =46-42 -> 4 | Q35: =F35+G35+H35+I35+J35+K35+L35+M35+N35+O35+P35 -> 7 | R35: ='01'!S35 -> 91618 | S35: 91660 | T35: =S35-R35 -> 42 | V35: 6 | Y35: =X35+W35+V35+U35 -> 6 | AD35: 11 | AG35: =Z35+AA35+AB35+AC35+AD35+AE35+AF35 -> 11 | AL35: =AH35+AI35 -> 0 | AM35: =AJ35+AK35 -> 0 | AN35: ='01'!AR35 -> 180 | AP35: =AO35+AN35 -> 180 | AQ35: =AP35-AR35 -> 50 | AR35: 130 | AS35: =AQ35/D35 -> 7.1428571 | AT35: ='01'!AT35 -> 250 | AU35: =AT35-AR35 -> 120 | AW35: =ROUNDUP(I35*AS35,0) -> 0 | AX35: =ROUNDUP(H35*AS35,0) -> 29 | AY35: =ROUNDUP(J35*AS35,0) -> 0 | BB35: =AQ35-AW35-AX35-AY35 -> 21
